2022-01-29 10:47:24,039 INFO     Started server process [22840]
2022-01-29 10:47:24,040 INFO     Waiting for application startup.
2022-01-29 10:47:24,041 INFO     Application startup complete.
2022-01-29 10:47:31,476 INFO     Displaying dashboard
2022-01-29 10:47:51,156 INFO     Started server process [14800]
2022-01-29 10:47:51,156 INFO     Waiting for application startup.
2022-01-29 10:47:51,160 INFO     Application startup complete.
2022-01-29 10:47:58,392 INFO     Displaying dashboard
2022-01-29 10:48:11,207 INFO     Shutting down
2022-01-29 10:48:11,323 INFO     Waiting for application shutdown.
2022-01-29 10:48:11,323 INFO     Application shutdown complete.
2022-01-29 10:48:11,323 INFO     Finished server process [14800]
2022-01-29 10:48:53,166 INFO     Started server process [20956]
2022-01-29 10:48:53,166 INFO     Waiting for application startup.
2022-01-29 10:48:53,166 INFO     Application startup complete.
2022-01-29 10:48:59,261 INFO     Displaying dashboard
2022-01-29 10:55:54,855 INFO     Started server process [31540]
2022-01-29 10:55:54,855 INFO     Waiting for application startup.
2022-01-29 10:55:54,861 INFO     Application startup complete.
2022-01-29 10:57:29,905 INFO     Started server process [29976]
2022-01-29 10:57:29,906 INFO     Waiting for application startup.
2022-01-29 10:57:29,907 INFO     Application startup complete.
2022-01-29 10:57:35,992 ERROR    Exception in ASGI application
Traceback (most recent call last):
  File "C:\Users\PatCa\anaconda3\lib\site-packages\uvicorn\protocols\http\h11_impl.py", line 373, in run_asgi
    result = await app(self.scope, self.receive, self.send)
  File "C:\Users\PatCa\anaconda3\lib\site-packages\uvicorn\middleware\proxy_headers.py", line 75, in __call__
    return await self.app(scope, receive, send)
  File "C:\Users\PatCa\anaconda3\lib\site-packages\fastapi\applications.py", line 208, in __call__
    await super().__call__(scope, receive, send)
  File "C:\Users\PatCa\anaconda3\lib\site-packages\starlette\applications.py", line 112, in __call__
    await self.middleware_stack(scope, receive, send)
  File "C:\Users\PatCa\anaconda3\lib\site-packages\starlette\middleware\errors.py", line 181, in __call__
    raise exc
  File "C:\Users\PatCa\anaconda3\lib\site-packages\starlette\middleware\errors.py", line 159, in __call__
    await self.app(scope, receive, _send)
  File "C:\Users\PatCa\anaconda3\lib\site-packages\starlette\exceptions.py", line 82, in __call__
    raise exc
  File "C:\Users\PatCa\anaconda3\lib\site-packages\starlette\exceptions.py", line 71, in __call__
    await self.app(scope, receive, sender)
  File "C:\Users\PatCa\anaconda3\lib\site-packages\starlette\routing.py", line 656, in __call__
    await route.handle(scope, receive, send)
  File "C:\Users\PatCa\anaconda3\lib\site-packages\starlette\routing.py", line 259, in handle
    await self.app(scope, receive, send)
  File "C:\Users\PatCa\anaconda3\lib\site-packages\starlette\routing.py", line 61, in app
    response = await func(request)
  File "C:\Users\PatCa\anaconda3\lib\site-packages\fastapi\routing.py", line 226, in app
    raw_response = await run_endpoint_function(
  File "C:\Users\PatCa\anaconda3\lib\site-packages\fastapi\routing.py", line 159, in run_endpoint_function
    return await dependant.call(**values)
  File ".\app\main.py", line 148, in baby_dashboard
    plot_feeding(feeding_json.json(), weight_json.json())
  File ".\app\plot_util.py", line 202, in plot_feeding
    plt.plot(df2_date, df2.J_ma3,color="yellow", label="Jen 3-day MA")
NameError: name 'df2_date' is not defined
2022-01-29 10:57:46,584 INFO     Started server process [24188]
2022-01-29 10:57:46,584 INFO     Waiting for application startup.
2022-01-29 10:57:46,592 INFO     Application startup complete.
2022-01-29 10:57:56,702 INFO     Displaying dashboard
2022-01-29 10:58:41,011 INFO     Started server process [9084]
2022-01-29 10:58:41,012 INFO     Waiting for application startup.
2022-01-29 10:58:41,013 INFO     Application startup complete.
2022-01-29 10:58:46,599 ERROR    Exception in ASGI application
Traceback (most recent call last):
  File "C:\Users\PatCa\anaconda3\lib\site-packages\uvicorn\protocols\http\h11_impl.py", line 373, in run_asgi
    result = await app(self.scope, self.receive, self.send)
  File "C:\Users\PatCa\anaconda3\lib\site-packages\uvicorn\middleware\proxy_headers.py", line 75, in __call__
    return await self.app(scope, receive, send)
  File "C:\Users\PatCa\anaconda3\lib\site-packages\fastapi\applications.py", line 208, in __call__
    await super().__call__(scope, receive, send)
  File "C:\Users\PatCa\anaconda3\lib\site-packages\starlette\applications.py", line 112, in __call__
    await self.middleware_stack(scope, receive, send)
  File "C:\Users\PatCa\anaconda3\lib\site-packages\starlette\middleware\errors.py", line 181, in __call__
    raise exc
  File "C:\Users\PatCa\anaconda3\lib\site-packages\starlette\middleware\errors.py", line 159, in __call__
    await self.app(scope, receive, _send)
  File "C:\Users\PatCa\anaconda3\lib\site-packages\starlette\exceptions.py", line 82, in __call__
    raise exc
  File "C:\Users\PatCa\anaconda3\lib\site-packages\starlette\exceptions.py", line 71, in __call__
    await self.app(scope, receive, sender)
  File "C:\Users\PatCa\anaconda3\lib\site-packages\starlette\routing.py", line 656, in __call__
    await route.handle(scope, receive, send)
  File "C:\Users\PatCa\anaconda3\lib\site-packages\starlette\routing.py", line 259, in handle
    await self.app(scope, receive, send)
  File "C:\Users\PatCa\anaconda3\lib\site-packages\starlette\routing.py", line 61, in app
    response = await func(request)
  File "C:\Users\PatCa\anaconda3\lib\site-packages\fastapi\routing.py", line 226, in app
    raw_response = await run_endpoint_function(
  File "C:\Users\PatCa\anaconda3\lib\site-packages\fastapi\routing.py", line 159, in run_endpoint_function
    return await dependant.call(**values)
  File ".\app\main.py", line 148, in baby_dashboard
    plot_feeding(feeding_json.json(), weight_json.json())
  File ".\app\plot_util.py", line 188, in plot_feeding
    df2["J_ma3"] = df2['total_vol'].rolling(3).average()
  File "C:\Users\PatCa\anaconda3\lib\site-packages\pandas\core\window\rolling.py", line 273, in __getattr__
    raise AttributeError(
AttributeError: 'Rolling' object has no attribute 'average'
2022-01-29 11:00:14,999 INFO     Started server process [18140]
2022-01-29 11:00:14,999 INFO     Waiting for application startup.
2022-01-29 11:00:15,007 INFO     Application startup complete.
2022-01-29 11:00:21,456 INFO     Displaying dashboard
2022-01-29 11:01:00,306 INFO     Started server process [26024]
2022-01-29 11:01:00,306 INFO     Waiting for application startup.
2022-01-29 11:01:00,310 INFO     Application startup complete.
2022-01-29 11:01:10,335 INFO     Displaying dashboard
2022-01-29 11:01:32,056 INFO     Started server process [30396]
2022-01-29 11:01:32,056 INFO     Waiting for application startup.
2022-01-29 11:01:32,070 INFO     Application startup complete.
2022-01-29 11:01:40,909 INFO     Displaying dashboard
2022-01-29 11:01:49,822 INFO     Started server process [31300]
2022-01-29 11:01:49,823 INFO     Waiting for application startup.
2022-01-29 11:01:49,824 INFO     Application startup complete.
2022-01-29 11:01:55,853 INFO     Displaying dashboard
2022-01-29 11:54:16,912 INFO     Started server process [21904]
2022-01-29 11:54:16,912 INFO     Waiting for application startup.
2022-01-29 11:54:16,927 INFO     Application startup complete.
2022-01-29 11:54:25,918 INFO     Started server process [29932]
2022-01-29 11:54:25,920 INFO     Waiting for application startup.
2022-01-29 11:54:25,920 INFO     Application startup complete.
2022-01-29 11:54:34,022 ERROR    Exception in ASGI application
Traceback (most recent call last):
  File "C:\Users\PatCa\anaconda3\lib\site-packages\httpx\_transports\default.py", line 62, in map_httpcore_exceptions
    yield
  File "C:\Users\PatCa\anaconda3\lib\site-packages\httpx\_transports\default.py", line 276, in handle_async_request
    ) = await self._pool.handle_async_request(
  File "C:\Users\PatCa\anaconda3\lib\site-packages\httpcore\_async\connection_pool.py", line 234, in handle_async_request
    response = await connection.handle_async_request(
  File "C:\Users\PatCa\anaconda3\lib\site-packages\httpcore\_async\connection.py", line 148, in handle_async_request
    return await self.connection.handle_async_request(
  File "C:\Users\PatCa\anaconda3\lib\site-packages\httpcore\_async\http11.py", line 128, in handle_async_request
    ) = await self._receive_response(timeout)
  File "C:\Users\PatCa\anaconda3\lib\site-packages\httpcore\_async\http11.py", line 189, in _receive_response
    event = await self._receive_event(timeout)
  File "C:\Users\PatCa\anaconda3\lib\site-packages\httpcore\_async\http11.py", line 225, in _receive_event
    data = await self.socket.read(self.READ_NUM_BYTES, timeout)
  File "C:\Users\PatCa\anaconda3\lib\site-packages\httpcore\_backends\anyio.py", line 63, in read
    raise ReadTimeout from None
httpcore.ReadTimeout

The above exception was the direct cause of the following exception:

Traceback (most recent call last):
  File "C:\Users\PatCa\anaconda3\lib\site-packages\uvicorn\protocols\http\h11_impl.py", line 373, in run_asgi
    result = await app(self.scope, self.receive, self.send)
  File "C:\Users\PatCa\anaconda3\lib\site-packages\uvicorn\middleware\proxy_headers.py", line 75, in __call__
    return await self.app(scope, receive, send)
  File "C:\Users\PatCa\anaconda3\lib\site-packages\fastapi\applications.py", line 208, in __call__
    await super().__call__(scope, receive, send)
  File "C:\Users\PatCa\anaconda3\lib\site-packages\starlette\applications.py", line 112, in __call__
    await self.middleware_stack(scope, receive, send)
  File "C:\Users\PatCa\anaconda3\lib\site-packages\starlette\middleware\errors.py", line 181, in __call__
    raise exc
  File "C:\Users\PatCa\anaconda3\lib\site-packages\starlette\middleware\errors.py", line 159, in __call__
    await self.app(scope, receive, _send)
  File "C:\Users\PatCa\anaconda3\lib\site-packages\starlette\exceptions.py", line 82, in __call__
    raise exc
  File "C:\Users\PatCa\anaconda3\lib\site-packages\starlette\exceptions.py", line 71, in __call__
    await self.app(scope, receive, sender)
  File "C:\Users\PatCa\anaconda3\lib\site-packages\starlette\routing.py", line 656, in __call__
    await route.handle(scope, receive, send)
  File "C:\Users\PatCa\anaconda3\lib\site-packages\starlette\routing.py", line 259, in handle
    await self.app(scope, receive, send)
  File "C:\Users\PatCa\anaconda3\lib\site-packages\starlette\routing.py", line 61, in app
    response = await func(request)
  File "C:\Users\PatCa\anaconda3\lib\site-packages\fastapi\routing.py", line 226, in app
    raw_response = await run_endpoint_function(
  File "C:\Users\PatCa\anaconda3\lib\site-packages\fastapi\routing.py", line 159, in run_endpoint_function
    return await dependant.call(**values)
  File ".\app\main.py", line 130, in baby_dashboard
    weight_json = await get_weight()
  File ".\app\data_handler.py", line 19, in get_weight
    w_json = await client.get(adr + "weight")
  File "C:\Users\PatCa\anaconda3\lib\site-packages\httpx\_client.py", line 1704, in get
    return await self.request(
  File "C:\Users\PatCa\anaconda3\lib\site-packages\httpx\_client.py", line 1483, in request
    response = await self.send(
  File "C:\Users\PatCa\anaconda3\lib\site-packages\httpx\_client.py", line 1571, in send
    response = await self._send_handling_auth(
  File "C:\Users\PatCa\anaconda3\lib\site-packages\httpx\_client.py", line 1599, in _send_handling_auth
    response = await self._send_handling_redirects(
  File "C:\Users\PatCa\anaconda3\lib\site-packages\httpx\_client.py", line 1636, in _send_handling_redirects
    response = await self._send_single_request(request)
  File "C:\Users\PatCa\anaconda3\lib\site-packages\httpx\_client.py", line 1673, in _send_single_request
    response = await transport.handle_async_request(request)
  File "C:\Users\PatCa\anaconda3\lib\site-packages\httpx\_transports\default.py", line 271, in handle_async_request
    (
  File "C:\Users\PatCa\anaconda3\lib\contextlib.py", line 131, in __exit__
    self.gen.throw(type, value, traceback)
  File "C:\Users\PatCa\anaconda3\lib\site-packages\httpx\_transports\default.py", line 79, in map_httpcore_exceptions
    raise mapped_exc(message) from exc
httpx.ReadTimeout
2022-01-29 11:54:54,435 INFO     Started server process [32628]
2022-01-29 11:54:54,435 INFO     Waiting for application startup.
2022-01-29 11:54:54,449 INFO     Application startup complete.
2022-01-29 11:55:07,605 INFO     Displaying dashboard
2022-01-29 11:55:24,931 INFO     Started server process [26060]
2022-01-29 11:55:24,931 INFO     Waiting for application startup.
2022-01-29 11:55:24,931 INFO     Application startup complete.
2022-01-29 11:56:16,393 INFO     Displaying dashboard
2022-01-29 11:57:06,651 INFO     Started server process [8176]
2022-01-29 11:57:06,653 INFO     Waiting for application startup.
2022-01-29 11:57:06,653 INFO     Application startup complete.
2022-01-29 11:57:13,783 INFO     Displaying dashboard
2022-01-30 10:16:05,873 ERROR    Exception in ASGI application
Traceback (most recent call last):
  File "C:\Users\PatCa\anaconda3\lib\site-packages\httpx\_transports\default.py", line 62, in map_httpcore_exceptions
    yield
  File "C:\Users\PatCa\anaconda3\lib\site-packages\httpx\_transports\default.py", line 276, in handle_async_request
    ) = await self._pool.handle_async_request(
  File "C:\Users\PatCa\anaconda3\lib\site-packages\httpcore\_async\connection_pool.py", line 234, in handle_async_request
    response = await connection.handle_async_request(
  File "C:\Users\PatCa\anaconda3\lib\site-packages\httpcore\_async\connection.py", line 148, in handle_async_request
    return await self.connection.handle_async_request(
  File "C:\Users\PatCa\anaconda3\lib\site-packages\httpcore\_async\http11.py", line 128, in handle_async_request
    ) = await self._receive_response(timeout)
  File "C:\Users\PatCa\anaconda3\lib\site-packages\httpcore\_async\http11.py", line 189, in _receive_response
    event = await self._receive_event(timeout)
  File "C:\Users\PatCa\anaconda3\lib\site-packages\httpcore\_async\http11.py", line 225, in _receive_event
    data = await self.socket.read(self.READ_NUM_BYTES, timeout)
  File "C:\Users\PatCa\anaconda3\lib\site-packages\httpcore\_backends\anyio.py", line 63, in read
    raise ReadTimeout from None
httpcore.ReadTimeout

The above exception was the direct cause of the following exception:

Traceback (most recent call last):
  File "C:\Users\PatCa\anaconda3\lib\site-packages\uvicorn\protocols\http\h11_impl.py", line 373, in run_asgi
    result = await app(self.scope, self.receive, self.send)
  File "C:\Users\PatCa\anaconda3\lib\site-packages\uvicorn\middleware\proxy_headers.py", line 75, in __call__
    return await self.app(scope, receive, send)
  File "C:\Users\PatCa\anaconda3\lib\site-packages\fastapi\applications.py", line 208, in __call__
    await super().__call__(scope, receive, send)
  File "C:\Users\PatCa\anaconda3\lib\site-packages\starlette\applications.py", line 112, in __call__
    await self.middleware_stack(scope, receive, send)
  File "C:\Users\PatCa\anaconda3\lib\site-packages\starlette\middleware\errors.py", line 181, in __call__
    raise exc
  File "C:\Users\PatCa\anaconda3\lib\site-packages\starlette\middleware\errors.py", line 159, in __call__
    await self.app(scope, receive, _send)
  File "C:\Users\PatCa\anaconda3\lib\site-packages\starlette\exceptions.py", line 82, in __call__
    raise exc
  File "C:\Users\PatCa\anaconda3\lib\site-packages\starlette\exceptions.py", line 71, in __call__
    await self.app(scope, receive, sender)
  File "C:\Users\PatCa\anaconda3\lib\site-packages\starlette\routing.py", line 656, in __call__
    await route.handle(scope, receive, send)
  File "C:\Users\PatCa\anaconda3\lib\site-packages\starlette\routing.py", line 259, in handle
    await self.app(scope, receive, send)
  File "C:\Users\PatCa\anaconda3\lib\site-packages\starlette\routing.py", line 61, in app
    response = await func(request)
  File "C:\Users\PatCa\anaconda3\lib\site-packages\fastapi\routing.py", line 226, in app
    raw_response = await run_endpoint_function(
  File "C:\Users\PatCa\anaconda3\lib\site-packages\fastapi\routing.py", line 159, in run_endpoint_function
    return await dependant.call(**values)
  File ".\app\main.py", line 130, in baby_dashboard
    weight_json = await get_weight()
  File ".\app\data_handler.py", line 19, in get_weight
    w_json = await client.get(adr + "weight")
  File "C:\Users\PatCa\anaconda3\lib\site-packages\httpx\_client.py", line 1704, in get
    return await self.request(
  File "C:\Users\PatCa\anaconda3\lib\site-packages\httpx\_client.py", line 1483, in request
    response = await self.send(
  File "C:\Users\PatCa\anaconda3\lib\site-packages\httpx\_client.py", line 1571, in send
    response = await self._send_handling_auth(
  File "C:\Users\PatCa\anaconda3\lib\site-packages\httpx\_client.py", line 1599, in _send_handling_auth
    response = await self._send_handling_redirects(
  File "C:\Users\PatCa\anaconda3\lib\site-packages\httpx\_client.py", line 1636, in _send_handling_redirects
    response = await self._send_single_request(request)
  File "C:\Users\PatCa\anaconda3\lib\site-packages\httpx\_client.py", line 1673, in _send_single_request
    response = await transport.handle_async_request(request)
  File "C:\Users\PatCa\anaconda3\lib\site-packages\httpx\_transports\default.py", line 271, in handle_async_request
    (
  File "C:\Users\PatCa\anaconda3\lib\contextlib.py", line 131, in __exit__
    self.gen.throw(type, value, traceback)
  File "C:\Users\PatCa\anaconda3\lib\site-packages\httpx\_transports\default.py", line 79, in map_httpcore_exceptions
    raise mapped_exc(message) from exc
httpx.ReadTimeout
2022-01-30 10:16:34,119 INFO     Displaying dashboard
2022-01-30 10:17:31,279 INFO     Shutting down
2022-01-30 10:30:13,924 INFO     Started server process [19596]
2022-01-30 10:30:13,925 INFO     Waiting for application startup.
2022-01-30 10:30:13,926 INFO     Application startup complete.
2022-01-30 10:30:31,384 INFO     Displaying dashboard
2022-01-30 10:30:31,396 ERROR    Exception in ASGI application
Traceback (most recent call last):
  File "C:\Users\PatCa\anaconda3\lib\site-packages\uvicorn\protocols\http\h11_impl.py", line 373, in run_asgi
    result = await app(self.scope, self.receive, self.send)
  File "C:\Users\PatCa\anaconda3\lib\site-packages\uvicorn\middleware\proxy_headers.py", line 75, in __call__
    return await self.app(scope, receive, send)
  File "C:\Users\PatCa\anaconda3\lib\site-packages\fastapi\applications.py", line 208, in __call__
    await super().__call__(scope, receive, send)
  File "C:\Users\PatCa\anaconda3\lib\site-packages\starlette\applications.py", line 112, in __call__
    await self.middleware_stack(scope, receive, send)
  File "C:\Users\PatCa\anaconda3\lib\site-packages\starlette\middleware\errors.py", line 181, in __call__
    raise exc
  File "C:\Users\PatCa\anaconda3\lib\site-packages\starlette\middleware\errors.py", line 159, in __call__
    await self.app(scope, receive, _send)
  File "C:\Users\PatCa\anaconda3\lib\site-packages\starlette\exceptions.py", line 82, in __call__
    raise exc
  File "C:\Users\PatCa\anaconda3\lib\site-packages\starlette\exceptions.py", line 71, in __call__
    await self.app(scope, receive, sender)
  File "C:\Users\PatCa\anaconda3\lib\site-packages\starlette\routing.py", line 656, in __call__
    await route.handle(scope, receive, send)
  File "C:\Users\PatCa\anaconda3\lib\site-packages\starlette\routing.py", line 259, in handle
    await self.app(scope, receive, send)
  File "C:\Users\PatCa\anaconda3\lib\site-packages\starlette\routing.py", line 61, in app
    response = await func(request)
  File "C:\Users\PatCa\anaconda3\lib\site-packages\fastapi\routing.py", line 226, in app
    raw_response = await run_endpoint_function(
  File "C:\Users\PatCa\anaconda3\lib\site-packages\fastapi\routing.py", line 159, in run_endpoint_function
    return await dependant.call(**values)
  File ".\app\main.py", line 153, in baby_dashboard
    return templates.TemplateResponse(
  File "C:\Users\PatCa\anaconda3\lib\site-packages\starlette\templating.py", line 86, in TemplateResponse
    template = self.get_template(name)
  File "C:\Users\PatCa\anaconda3\lib\site-packages\starlette\templating.py", line 73, in get_template
    return self.env.get_template(name)
  File "C:\Users\PatCa\anaconda3\lib\site-packages\jinja2\environment.py", line 883, in get_template
    return self._load_template(name, self.make_globals(globals))
  File "C:\Users\PatCa\anaconda3\lib\site-packages\jinja2\environment.py", line 857, in _load_template
    template = self.loader.load(self, name, globals)
  File "C:\Users\PatCa\anaconda3\lib\site-packages\jinja2\loaders.py", line 127, in load
    code = environment.compile(source, name, filename)
  File "C:\Users\PatCa\anaconda3\lib\site-packages\jinja2\environment.py", line 638, in compile
    self.handle_exception(source=source_hint)
  File "C:\Users\PatCa\anaconda3\lib\site-packages\jinja2\environment.py", line 832, in handle_exception
    reraise(*rewrite_traceback_stack(source=source))
  File "C:\Users\PatCa\anaconda3\lib\site-packages\jinja2\_compat.py", line 28, in reraise
    raise value.with_traceback(tb)
  File "C:\Users\PatCa\Documents\PythonScripts\baby_growth\baby_dashboard\templates\dashboard.html", line 18, in template
    {% block title %}
jinja2.exceptions.TemplateAssertionError: block 'title' defined twice
2022-01-30 10:32:22,599 INFO     Displaying dashboard
2022-01-30 10:32:29,566 INFO     Reset db
2022-01-30 10:32:36,331 INFO     Displaying dashboard
2022-01-30 10:35:35,127 INFO     Displaying dashboard
2022-01-30 10:35:37,197 ERROR    Exception in ASGI application
Traceback (most recent call last):
  File "C:\Users\PatCa\anaconda3\lib\site-packages\uvicorn\protocols\http\h11_impl.py", line 373, in run_asgi
    result = await app(self.scope, self.receive, self.send)
  File "C:\Users\PatCa\anaconda3\lib\site-packages\uvicorn\middleware\proxy_headers.py", line 75, in __call__
    return await self.app(scope, receive, send)
  File "C:\Users\PatCa\anaconda3\lib\site-packages\fastapi\applications.py", line 208, in __call__
    await super().__call__(scope, receive, send)
  File "C:\Users\PatCa\anaconda3\lib\site-packages\starlette\applications.py", line 112, in __call__
    await self.middleware_stack(scope, receive, send)
  File "C:\Users\PatCa\anaconda3\lib\site-packages\starlette\middleware\errors.py", line 181, in __call__
    raise exc
  File "C:\Users\PatCa\anaconda3\lib\site-packages\starlette\middleware\errors.py", line 159, in __call__
    await self.app(scope, receive, _send)
  File "C:\Users\PatCa\anaconda3\lib\site-packages\starlette\exceptions.py", line 82, in __call__
    raise exc
  File "C:\Users\PatCa\anaconda3\lib\site-packages\starlette\exceptions.py", line 71, in __call__
    await self.app(scope, receive, sender)
  File "C:\Users\PatCa\anaconda3\lib\site-packages\starlette\routing.py", line 656, in __call__
    await route.handle(scope, receive, send)
  File "C:\Users\PatCa\anaconda3\lib\site-packages\starlette\routing.py", line 259, in handle
    await self.app(scope, receive, send)
  File "C:\Users\PatCa\anaconda3\lib\site-packages\starlette\routing.py", line 61, in app
    response = await func(request)
  File "C:\Users\PatCa\anaconda3\lib\site-packages\fastapi\routing.py", line 226, in app
    raw_response = await run_endpoint_function(
  File "C:\Users\PatCa\anaconda3\lib\site-packages\fastapi\routing.py", line 161, in run_endpoint_function
    return await run_in_threadpool(dependant.call, **values)
  File "C:\Users\PatCa\anaconda3\lib\site-packages\starlette\concurrency.py", line 39, in run_in_threadpool
    return await anyio.to_thread.run_sync(func, *args)
  File "C:\Users\PatCa\anaconda3\lib\site-packages\anyio\to_thread.py", line 28, in run_sync
    return await get_asynclib().run_sync_in_worker_thread(func, *args, cancellable=cancellable,
  File "C:\Users\PatCa\anaconda3\lib\site-packages\anyio\_backends\_asyncio.py", line 805, in run_sync_in_worker_thread
    return await future
  File "C:\Users\PatCa\anaconda3\lib\site-packages\anyio\_backends\_asyncio.py", line 743, in run
    result = func(*args)
  File ".\app\main.py", line 159, in data_update_get
    return templates.TemplateResponse("data_update.html", {"request": request})
  File "C:\Users\PatCa\anaconda3\lib\site-packages\starlette\templating.py", line 86, in TemplateResponse
    template = self.get_template(name)
  File "C:\Users\PatCa\anaconda3\lib\site-packages\starlette\templating.py", line 73, in get_template
    return self.env.get_template(name)
  File "C:\Users\PatCa\anaconda3\lib\site-packages\jinja2\environment.py", line 883, in get_template
    return self._load_template(name, self.make_globals(globals))
  File "C:\Users\PatCa\anaconda3\lib\site-packages\jinja2\environment.py", line 857, in _load_template
    template = self.loader.load(self, name, globals)
  File "C:\Users\PatCa\anaconda3\lib\site-packages\jinja2\loaders.py", line 127, in load
    code = environment.compile(source, name, filename)
  File "C:\Users\PatCa\anaconda3\lib\site-packages\jinja2\environment.py", line 638, in compile
    self.handle_exception(source=source_hint)
  File "C:\Users\PatCa\anaconda3\lib\site-packages\jinja2\environment.py", line 832, in handle_exception
    reraise(*rewrite_traceback_stack(source=source))
  File "C:\Users\PatCa\anaconda3\lib\site-packages\jinja2\_compat.py", line 28, in reraise
    raise value.with_traceback(tb)
  File "C:\Users\PatCa\Documents\PythonScripts\baby_growth\baby_dashboard\templates\data_update.html", line 7, in template
    {% block content}
jinja2.exceptions.TemplateSyntaxError: unexpected '}'
2022-01-30 10:36:03,876 ERROR    Exception in ASGI application
Traceback (most recent call last):
  File "C:\Users\PatCa\anaconda3\lib\site-packages\uvicorn\protocols\http\h11_impl.py", line 373, in run_asgi
    result = await app(self.scope, self.receive, self.send)
  File "C:\Users\PatCa\anaconda3\lib\site-packages\uvicorn\middleware\proxy_headers.py", line 75, in __call__
    return await self.app(scope, receive, send)
  File "C:\Users\PatCa\anaconda3\lib\site-packages\fastapi\applications.py", line 208, in __call__
    await super().__call__(scope, receive, send)
  File "C:\Users\PatCa\anaconda3\lib\site-packages\starlette\applications.py", line 112, in __call__
    await self.middleware_stack(scope, receive, send)
  File "C:\Users\PatCa\anaconda3\lib\site-packages\starlette\middleware\errors.py", line 181, in __call__
    raise exc
  File "C:\Users\PatCa\anaconda3\lib\site-packages\starlette\middleware\errors.py", line 159, in __call__
    await self.app(scope, receive, _send)
  File "C:\Users\PatCa\anaconda3\lib\site-packages\starlette\exceptions.py", line 82, in __call__
    raise exc
  File "C:\Users\PatCa\anaconda3\lib\site-packages\starlette\exceptions.py", line 71, in __call__
    await self.app(scope, receive, sender)
  File "C:\Users\PatCa\anaconda3\lib\site-packages\starlette\routing.py", line 656, in __call__
    await route.handle(scope, receive, send)
  File "C:\Users\PatCa\anaconda3\lib\site-packages\starlette\routing.py", line 259, in handle
    await self.app(scope, receive, send)
  File "C:\Users\PatCa\anaconda3\lib\site-packages\starlette\routing.py", line 61, in app
    response = await func(request)
  File "C:\Users\PatCa\anaconda3\lib\site-packages\fastapi\routing.py", line 226, in app
    raw_response = await run_endpoint_function(
  File "C:\Users\PatCa\anaconda3\lib\site-packages\fastapi\routing.py", line 161, in run_endpoint_function
    return await run_in_threadpool(dependant.call, **values)
  File "C:\Users\PatCa\anaconda3\lib\site-packages\starlette\concurrency.py", line 39, in run_in_threadpool
    return await anyio.to_thread.run_sync(func, *args)
  File "C:\Users\PatCa\anaconda3\lib\site-packages\anyio\to_thread.py", line 28, in run_sync
    return await get_asynclib().run_sync_in_worker_thread(func, *args, cancellable=cancellable,
  File "C:\Users\PatCa\anaconda3\lib\site-packages\anyio\_backends\_asyncio.py", line 805, in run_sync_in_worker_thread
    return await future
  File "C:\Users\PatCa\anaconda3\lib\site-packages\anyio\_backends\_asyncio.py", line 743, in run
    result = func(*args)
  File ".\app\main.py", line 159, in data_update_get
    return templates.TemplateResponse("data_update.html", {"request": request})
  File "C:\Users\PatCa\anaconda3\lib\site-packages\starlette\templating.py", line 86, in TemplateResponse
    template = self.get_template(name)
  File "C:\Users\PatCa\anaconda3\lib\site-packages\starlette\templating.py", line 73, in get_template
    return self.env.get_template(name)
  File "C:\Users\PatCa\anaconda3\lib\site-packages\jinja2\environment.py", line 883, in get_template
    return self._load_template(name, self.make_globals(globals))
  File "C:\Users\PatCa\anaconda3\lib\site-packages\jinja2\environment.py", line 857, in _load_template
    template = self.loader.load(self, name, globals)
  File "C:\Users\PatCa\anaconda3\lib\site-packages\jinja2\loaders.py", line 127, in load
    code = environment.compile(source, name, filename)
  File "C:\Users\PatCa\anaconda3\lib\site-packages\jinja2\environment.py", line 638, in compile
    self.handle_exception(source=source_hint)
  File "C:\Users\PatCa\anaconda3\lib\site-packages\jinja2\environment.py", line 832, in handle_exception
    reraise(*rewrite_traceback_stack(source=source))
  File "C:\Users\PatCa\anaconda3\lib\site-packages\jinja2\_compat.py", line 28, in reraise
    raise value.with_traceback(tb)
  File "C:\Users\PatCa\Documents\PythonScripts\baby_growth\baby_dashboard\templates\data_update.html", line 7, in template
    {% block content}
jinja2.exceptions.TemplateSyntaxError: unexpected '}'
2022-01-30 10:36:04,154 ERROR    Exception in ASGI application
Traceback (most recent call last):
  File "C:\Users\PatCa\anaconda3\lib\site-packages\uvicorn\protocols\http\h11_impl.py", line 373, in run_asgi
    result = await app(self.scope, self.receive, self.send)
  File "C:\Users\PatCa\anaconda3\lib\site-packages\uvicorn\middleware\proxy_headers.py", line 75, in __call__
    return await self.app(scope, receive, send)
  File "C:\Users\PatCa\anaconda3\lib\site-packages\fastapi\applications.py", line 208, in __call__
    await super().__call__(scope, receive, send)
  File "C:\Users\PatCa\anaconda3\lib\site-packages\starlette\applications.py", line 112, in __call__
    await self.middleware_stack(scope, receive, send)
  File "C:\Users\PatCa\anaconda3\lib\site-packages\starlette\middleware\errors.py", line 181, in __call__
    raise exc
  File "C:\Users\PatCa\anaconda3\lib\site-packages\starlette\middleware\errors.py", line 159, in __call__
    await self.app(scope, receive, _send)
  File "C:\Users\PatCa\anaconda3\lib\site-packages\starlette\exceptions.py", line 82, in __call__
    raise exc
  File "C:\Users\PatCa\anaconda3\lib\site-packages\starlette\exceptions.py", line 71, in __call__
    await self.app(scope, receive, sender)
  File "C:\Users\PatCa\anaconda3\lib\site-packages\starlette\routing.py", line 656, in __call__
    await route.handle(scope, receive, send)
  File "C:\Users\PatCa\anaconda3\lib\site-packages\starlette\routing.py", line 259, in handle
    await self.app(scope, receive, send)
  File "C:\Users\PatCa\anaconda3\lib\site-packages\starlette\routing.py", line 61, in app
    response = await func(request)
  File "C:\Users\PatCa\anaconda3\lib\site-packages\fastapi\routing.py", line 226, in app
    raw_response = await run_endpoint_function(
  File "C:\Users\PatCa\anaconda3\lib\site-packages\fastapi\routing.py", line 161, in run_endpoint_function
    return await run_in_threadpool(dependant.call, **values)
  File "C:\Users\PatCa\anaconda3\lib\site-packages\starlette\concurrency.py", line 39, in run_in_threadpool
    return await anyio.to_thread.run_sync(func, *args)
  File "C:\Users\PatCa\anaconda3\lib\site-packages\anyio\to_thread.py", line 28, in run_sync
    return await get_asynclib().run_sync_in_worker_thread(func, *args, cancellable=cancellable,
  File "C:\Users\PatCa\anaconda3\lib\site-packages\anyio\_backends\_asyncio.py", line 805, in run_sync_in_worker_thread
    return await future
  File "C:\Users\PatCa\anaconda3\lib\site-packages\anyio\_backends\_asyncio.py", line 743, in run
    result = func(*args)
  File ".\app\main.py", line 159, in data_update_get
    return templates.TemplateResponse("data_update.html", {"request": request})
  File "C:\Users\PatCa\anaconda3\lib\site-packages\starlette\templating.py", line 86, in TemplateResponse
    template = self.get_template(name)
  File "C:\Users\PatCa\anaconda3\lib\site-packages\starlette\templating.py", line 73, in get_template
    return self.env.get_template(name)
  File "C:\Users\PatCa\anaconda3\lib\site-packages\jinja2\environment.py", line 883, in get_template
    return self._load_template(name, self.make_globals(globals))
  File "C:\Users\PatCa\anaconda3\lib\site-packages\jinja2\environment.py", line 857, in _load_template
    template = self.loader.load(self, name, globals)
  File "C:\Users\PatCa\anaconda3\lib\site-packages\jinja2\loaders.py", line 127, in load
    code = environment.compile(source, name, filename)
  File "C:\Users\PatCa\anaconda3\lib\site-packages\jinja2\environment.py", line 638, in compile
    self.handle_exception(source=source_hint)
  File "C:\Users\PatCa\anaconda3\lib\site-packages\jinja2\environment.py", line 832, in handle_exception
    reraise(*rewrite_traceback_stack(source=source))
  File "C:\Users\PatCa\anaconda3\lib\site-packages\jinja2\_compat.py", line 28, in reraise
    raise value.with_traceback(tb)
  File "C:\Users\PatCa\Documents\PythonScripts\baby_growth\baby_dashboard\templates\data_update.html", line 7, in template
    {% block content}
jinja2.exceptions.TemplateSyntaxError: unexpected '}'
2022-01-30 10:37:29,455 INFO     Reset db
2022-01-30 10:37:36,483 INFO     Displaying dashboard
2022-01-30 10:39:29,006 INFO     Started server process [7048]
2022-01-30 10:39:29,007 INFO     Waiting for application startup.
2022-01-30 10:39:29,007 INFO     Application startup complete.
2022-01-30 10:39:33,755 INFO     Started server process [30148]
2022-01-30 10:39:33,757 INFO     Waiting for application startup.
2022-01-30 10:39:33,757 INFO     Application startup complete.
2022-01-30 10:39:41,646 INFO     Reset db
2022-01-30 10:39:47,892 INFO     Displaying dashboard
2022-01-30 10:41:02,947 INFO     Started server process [32336]
2022-01-30 10:41:02,948 INFO     Waiting for application startup.
2022-01-30 10:41:02,950 INFO     Application startup complete.
2022-01-30 10:41:13,734 INFO     Reset db
2022-01-30 10:41:29,377 INFO     Displaying dashboard
2022-01-30 10:42:48,401 INFO     Started server process [18408]
2022-01-30 10:42:48,402 INFO     Waiting for application startup.
2022-01-30 10:42:48,403 INFO     Application startup complete.
2022-01-30 10:42:56,223 INFO     Started server process [13776]
2022-01-30 10:42:56,223 INFO     Waiting for application startup.
2022-01-30 10:42:56,229 INFO     Application startup complete.
2022-01-30 10:43:03,090 INFO     Updating head data
2022-01-30 10:43:09,763 INFO     Displaying dashboard
2022-01-30 10:43:19,221 INFO     Reset db
2022-01-30 10:43:25,512 INFO     Displaying dashboard
2022-01-30 10:43:56,159 INFO     Started server process [19596]
2022-01-30 10:43:56,160 INFO     Waiting for application startup.
2022-01-30 10:43:56,161 INFO     Application startup complete.
2022-01-30 10:44:08,967 INFO     Shutting down
2022-01-30 10:48:06,042 INFO     Started server process [30896]
2022-01-30 10:48:06,042 INFO     Waiting for application startup.
2022-01-30 10:48:06,056 INFO     Application startup complete.
2022-01-30 10:48:29,854 INFO     Displaying dashboard
2022-01-30 10:48:35,917 INFO     Reset db
2022-01-30 10:48:42,051 INFO     Displaying dashboard
