2022-01-26 16:24:39,415 INFO     Started server process [14056]
2022-01-26 16:24:39,417 INFO     Waiting for application startup.
2022-01-26 16:24:39,419 INFO     Application startup complete.
2022-01-26 16:25:18,010 ERROR    Exception in ASGI application
Traceback (most recent call last):
  File "C:\Users\PatCa\anaconda3\lib\site-packages\httpx\_transports\default.py", line 62, in map_httpcore_exceptions
    yield
  File "C:\Users\PatCa\anaconda3\lib\site-packages\httpx\_transports\default.py", line 276, in handle_async_request
    ) = await self._pool.handle_async_request(
  File "C:\Users\PatCa\anaconda3\lib\site-packages\httpcore\_async\connection_pool.py", line 234, in handle_async_request
    response = await connection.handle_async_request(
  File "C:\Users\PatCa\anaconda3\lib\site-packages\httpcore\_async\connection.py", line 148, in handle_async_request
    return await self.connection.handle_async_request(
  File "C:\Users\PatCa\anaconda3\lib\site-packages\httpcore\_async\http11.py", line 128, in handle_async_request
    ) = await self._receive_response(timeout)
  File "C:\Users\PatCa\anaconda3\lib\site-packages\httpcore\_async\http11.py", line 189, in _receive_response
    event = await self._receive_event(timeout)
  File "C:\Users\PatCa\anaconda3\lib\site-packages\httpcore\_async\http11.py", line 225, in _receive_event
    data = await self.socket.read(self.READ_NUM_BYTES, timeout)
  File "C:\Users\PatCa\anaconda3\lib\site-packages\httpcore\_backends\anyio.py", line 63, in read
    raise ReadTimeout from None
httpcore.ReadTimeout

The above exception was the direct cause of the following exception:

Traceback (most recent call last):
  File "C:\Users\PatCa\anaconda3\lib\site-packages\uvicorn\protocols\http\h11_impl.py", line 373, in run_asgi
    result = await app(self.scope, self.receive, self.send)
  File "C:\Users\PatCa\anaconda3\lib\site-packages\uvicorn\middleware\proxy_headers.py", line 75, in __call__
    return await self.app(scope, receive, send)
  File "C:\Users\PatCa\anaconda3\lib\site-packages\fastapi\applications.py", line 208, in __call__
    await super().__call__(scope, receive, send)
  File "C:\Users\PatCa\anaconda3\lib\site-packages\starlette\applications.py", line 112, in __call__
    await self.middleware_stack(scope, receive, send)
  File "C:\Users\PatCa\anaconda3\lib\site-packages\starlette\middleware\errors.py", line 181, in __call__
    raise exc
  File "C:\Users\PatCa\anaconda3\lib\site-packages\starlette\middleware\errors.py", line 159, in __call__
    await self.app(scope, receive, _send)
  File "C:\Users\PatCa\anaconda3\lib\site-packages\starlette\exceptions.py", line 82, in __call__
    raise exc
  File "C:\Users\PatCa\anaconda3\lib\site-packages\starlette\exceptions.py", line 71, in __call__
    await self.app(scope, receive, sender)
  File "C:\Users\PatCa\anaconda3\lib\site-packages\starlette\routing.py", line 656, in __call__
    await route.handle(scope, receive, send)
  File "C:\Users\PatCa\anaconda3\lib\site-packages\starlette\routing.py", line 259, in handle
    await self.app(scope, receive, send)
  File "C:\Users\PatCa\anaconda3\lib\site-packages\starlette\routing.py", line 61, in app
    response = await func(request)
  File "C:\Users\PatCa\anaconda3\lib\site-packages\fastapi\routing.py", line 226, in app
    raw_response = await run_endpoint_function(
  File "C:\Users\PatCa\anaconda3\lib\site-packages\fastapi\routing.py", line 159, in run_endpoint_function
    return await dependant.call(**values)
  File ".\app\main.py", line 54, in baby_weight
    weight_json = await get_weight()
  File ".\app\data_handler.py", line 15, in get_weight
    w_json = await client.get(adr + "weight")
  File "C:\Users\PatCa\anaconda3\lib\site-packages\httpx\_client.py", line 1704, in get
    return await self.request(
  File "C:\Users\PatCa\anaconda3\lib\site-packages\httpx\_client.py", line 1483, in request
    response = await self.send(
  File "C:\Users\PatCa\anaconda3\lib\site-packages\httpx\_client.py", line 1571, in send
    response = await self._send_handling_auth(
  File "C:\Users\PatCa\anaconda3\lib\site-packages\httpx\_client.py", line 1599, in _send_handling_auth
    response = await self._send_handling_redirects(
  File "C:\Users\PatCa\anaconda3\lib\site-packages\httpx\_client.py", line 1636, in _send_handling_redirects
    response = await self._send_single_request(request)
  File "C:\Users\PatCa\anaconda3\lib\site-packages\httpx\_client.py", line 1673, in _send_single_request
    response = await transport.handle_async_request(request)
  File "C:\Users\PatCa\anaconda3\lib\site-packages\httpx\_transports\default.py", line 271, in handle_async_request
    (
  File "C:\Users\PatCa\anaconda3\lib\contextlib.py", line 131, in __exit__
    self.gen.throw(type, value, traceback)
  File "C:\Users\PatCa\anaconda3\lib\site-packages\httpx\_transports\default.py", line 79, in map_httpcore_exceptions
    raise mapped_exc(message) from exc
httpx.ReadTimeout
2022-01-26 16:26:07,513 INFO     Started server process [3856]
2022-01-26 16:26:07,513 INFO     Waiting for application startup.
2022-01-26 16:26:07,518 INFO     Application startup complete.
2022-01-26 16:26:37,023 INFO     Started server process [10588]
2022-01-26 16:26:37,024 INFO     Waiting for application startup.
2022-01-26 16:26:37,024 INFO     Application startup complete.
2022-01-26 16:26:58,598 INFO     Displaying dashboard
2022-01-26 16:27:20,363 INFO     Reset db
2022-01-26 16:27:27,188 INFO     Displaying dashboard
2022-01-26 16:27:58,312 INFO     Started server process [26792]
2022-01-26 16:27:58,313 INFO     Waiting for application startup.
2022-01-26 16:27:58,314 INFO     Application startup complete.
2022-01-26 16:28:02,965 INFO     Started server process [16824]
2022-01-26 16:28:02,966 INFO     Waiting for application startup.
2022-01-26 16:28:02,967 INFO     Application startup complete.
2022-01-26 16:28:22,441 INFO     Shutting down
2022-01-26 16:28:22,546 INFO     Waiting for application shutdown.
2022-01-26 16:28:22,546 INFO     Application shutdown complete.
2022-01-26 16:28:22,547 INFO     Finished server process [16824]
2022-01-27 10:51:34,742 INFO     Started server process [21116]
2022-01-27 10:51:34,743 INFO     Waiting for application startup.
2022-01-27 10:51:34,744 INFO     Application startup complete.
2022-01-27 10:51:58,492 ERROR    Exception in ASGI application
Traceback (most recent call last):
  File "C:\Users\PatCa\anaconda3\lib\site-packages\httpx\_transports\default.py", line 62, in map_httpcore_exceptions
    yield
  File "C:\Users\PatCa\anaconda3\lib\site-packages\httpx\_transports\default.py", line 276, in handle_async_request
    ) = await self._pool.handle_async_request(
  File "C:\Users\PatCa\anaconda3\lib\site-packages\httpcore\_async\connection_pool.py", line 234, in handle_async_request
    response = await connection.handle_async_request(
  File "C:\Users\PatCa\anaconda3\lib\site-packages\httpcore\_async\connection.py", line 148, in handle_async_request
    return await self.connection.handle_async_request(
  File "C:\Users\PatCa\anaconda3\lib\site-packages\httpcore\_async\http11.py", line 128, in handle_async_request
    ) = await self._receive_response(timeout)
  File "C:\Users\PatCa\anaconda3\lib\site-packages\httpcore\_async\http11.py", line 189, in _receive_response
    event = await self._receive_event(timeout)
  File "C:\Users\PatCa\anaconda3\lib\site-packages\httpcore\_async\http11.py", line 225, in _receive_event
    data = await self.socket.read(self.READ_NUM_BYTES, timeout)
  File "C:\Users\PatCa\anaconda3\lib\site-packages\httpcore\_backends\anyio.py", line 63, in read
    raise ReadTimeout from None
httpcore.ReadTimeout

The above exception was the direct cause of the following exception:

Traceback (most recent call last):
  File "C:\Users\PatCa\anaconda3\lib\site-packages\uvicorn\protocols\http\h11_impl.py", line 373, in run_asgi
    result = await app(self.scope, self.receive, self.send)
  File "C:\Users\PatCa\anaconda3\lib\site-packages\uvicorn\middleware\proxy_headers.py", line 75, in __call__
    return await self.app(scope, receive, send)
  File "C:\Users\PatCa\anaconda3\lib\site-packages\fastapi\applications.py", line 208, in __call__
    await super().__call__(scope, receive, send)
  File "C:\Users\PatCa\anaconda3\lib\site-packages\starlette\applications.py", line 112, in __call__
    await self.middleware_stack(scope, receive, send)
  File "C:\Users\PatCa\anaconda3\lib\site-packages\starlette\middleware\errors.py", line 181, in __call__
    raise exc
  File "C:\Users\PatCa\anaconda3\lib\site-packages\starlette\middleware\errors.py", line 159, in __call__
    await self.app(scope, receive, _send)
  File "C:\Users\PatCa\anaconda3\lib\site-packages\starlette\exceptions.py", line 82, in __call__
    raise exc
  File "C:\Users\PatCa\anaconda3\lib\site-packages\starlette\exceptions.py", line 71, in __call__
    await self.app(scope, receive, sender)
  File "C:\Users\PatCa\anaconda3\lib\site-packages\starlette\routing.py", line 656, in __call__
    await route.handle(scope, receive, send)
  File "C:\Users\PatCa\anaconda3\lib\site-packages\starlette\routing.py", line 259, in handle
    await self.app(scope, receive, send)
  File "C:\Users\PatCa\anaconda3\lib\site-packages\starlette\routing.py", line 61, in app
    response = await func(request)
  File "C:\Users\PatCa\anaconda3\lib\site-packages\fastapi\routing.py", line 226, in app
    raw_response = await run_endpoint_function(
  File "C:\Users\PatCa\anaconda3\lib\site-packages\fastapi\routing.py", line 159, in run_endpoint_function
    return await dependant.call(**values)
  File ".\app\main.py", line 130, in baby_dashboard
    weight_json = await get_weight()
  File ".\app\data_handler.py", line 15, in get_weight
    w_json = await client.get(adr + "weight")
  File "C:\Users\PatCa\anaconda3\lib\site-packages\httpx\_client.py", line 1704, in get
    return await self.request(
  File "C:\Users\PatCa\anaconda3\lib\site-packages\httpx\_client.py", line 1483, in request
    response = await self.send(
  File "C:\Users\PatCa\anaconda3\lib\site-packages\httpx\_client.py", line 1571, in send
    response = await self._send_handling_auth(
  File "C:\Users\PatCa\anaconda3\lib\site-packages\httpx\_client.py", line 1599, in _send_handling_auth
    response = await self._send_handling_redirects(
  File "C:\Users\PatCa\anaconda3\lib\site-packages\httpx\_client.py", line 1636, in _send_handling_redirects
    response = await self._send_single_request(request)
  File "C:\Users\PatCa\anaconda3\lib\site-packages\httpx\_client.py", line 1673, in _send_single_request
    response = await transport.handle_async_request(request)
  File "C:\Users\PatCa\anaconda3\lib\site-packages\httpx\_transports\default.py", line 271, in handle_async_request
    (
  File "C:\Users\PatCa\anaconda3\lib\contextlib.py", line 131, in __exit__
    self.gen.throw(type, value, traceback)
  File "C:\Users\PatCa\anaconda3\lib\site-packages\httpx\_transports\default.py", line 79, in map_httpcore_exceptions
    raise mapped_exc(message) from exc
httpx.ReadTimeout
2022-01-27 10:52:21,608 INFO     Displaying dashboard
2022-01-27 10:52:40,120 INFO     Updating head data
2022-01-27 10:52:46,135 INFO     Displaying dashboard
2022-01-27 10:53:00,160 INFO     Reset db
2022-01-27 10:53:06,224 INFO     Displaying dashboard
2022-01-27 10:53:40,858 INFO     Started server process [33540]
2022-01-27 10:53:40,858 INFO     Waiting for application startup.
2022-01-27 10:53:40,866 INFO     Application startup complete.
2022-01-27 10:53:57,567 INFO     Reset db
2022-01-27 10:54:03,595 INFO     Displaying dashboard
2022-01-27 10:56:08,216 INFO     Started server process [13332]
2022-01-27 10:56:08,216 INFO     Waiting for application startup.
2022-01-27 10:56:08,231 INFO     Application startup complete.
2022-01-27 10:57:36,712 INFO     Displaying dashboard
2022-01-27 11:03:43,724 INFO     Displaying dashboard
2022-01-27 11:03:58,130 INFO     Displaying dashboard
2022-01-27 11:04:09,115 INFO     Shutting down
2022-01-27 11:04:09,220 INFO     Waiting for application shutdown.
2022-01-27 11:04:09,221 INFO     Application shutdown complete.
2022-01-27 11:04:09,221 INFO     Finished server process [13332]
2022-01-27 13:32:20,325 INFO     Started server process [28608]
2022-01-27 13:32:20,325 INFO     Waiting for application startup.
2022-01-27 13:32:20,337 INFO     Application startup complete.
2022-01-27 13:32:39,921 INFO     Displaying dashboard
2022-01-27 13:32:50,292 INFO     Updating head data
2022-01-27 13:33:38,294 INFO     Started server process [17320]
2022-01-27 13:33:38,295 INFO     Waiting for application startup.
2022-01-27 13:33:38,295 INFO     Application startup complete.
2022-01-27 13:33:42,478 INFO     Reset db
2022-01-27 13:34:00,474 INFO     Updating head data
2022-01-27 13:34:12,656 INFO     Displaying dashboard
2022-01-27 13:34:27,567 INFO     Shutting down
2022-01-27 13:34:27,679 INFO     Waiting for application shutdown.
2022-01-27 13:34:27,679 INFO     Application shutdown complete.
2022-01-27 13:34:27,679 INFO     Finished server process [17320]
2022-01-27 14:43:06,844 INFO     Started server process [31256]
2022-01-27 14:43:06,845 INFO     Waiting for application startup.
2022-01-27 14:43:06,846 INFO     Application startup complete.
2022-01-27 14:43:16,615 ERROR    Exception in ASGI application
Traceback (most recent call last):
  File "C:\Users\PatCa\anaconda3\lib\site-packages\httpx\_transports\default.py", line 62, in map_httpcore_exceptions
    yield
  File "C:\Users\PatCa\anaconda3\lib\site-packages\httpx\_transports\default.py", line 276, in handle_async_request
    ) = await self._pool.handle_async_request(
  File "C:\Users\PatCa\anaconda3\lib\site-packages\httpcore\_async\connection_pool.py", line 234, in handle_async_request
    response = await connection.handle_async_request(
  File "C:\Users\PatCa\anaconda3\lib\site-packages\httpcore\_async\connection.py", line 148, in handle_async_request
    return await self.connection.handle_async_request(
  File "C:\Users\PatCa\anaconda3\lib\site-packages\httpcore\_async\http11.py", line 128, in handle_async_request
    ) = await self._receive_response(timeout)
  File "C:\Users\PatCa\anaconda3\lib\site-packages\httpcore\_async\http11.py", line 189, in _receive_response
    event = await self._receive_event(timeout)
  File "C:\Users\PatCa\anaconda3\lib\site-packages\httpcore\_async\http11.py", line 225, in _receive_event
    data = await self.socket.read(self.READ_NUM_BYTES, timeout)
  File "C:\Users\PatCa\anaconda3\lib\site-packages\httpcore\_backends\anyio.py", line 63, in read
    raise ReadTimeout from None
httpcore.ReadTimeout

The above exception was the direct cause of the following exception:

Traceback (most recent call last):
  File "C:\Users\PatCa\anaconda3\lib\site-packages\uvicorn\protocols\http\h11_impl.py", line 373, in run_asgi
    result = await app(self.scope, self.receive, self.send)
  File "C:\Users\PatCa\anaconda3\lib\site-packages\uvicorn\middleware\proxy_headers.py", line 75, in __call__
    return await self.app(scope, receive, send)
  File "C:\Users\PatCa\anaconda3\lib\site-packages\fastapi\applications.py", line 208, in __call__
    await super().__call__(scope, receive, send)
  File "C:\Users\PatCa\anaconda3\lib\site-packages\starlette\applications.py", line 112, in __call__
    await self.middleware_stack(scope, receive, send)
  File "C:\Users\PatCa\anaconda3\lib\site-packages\starlette\middleware\errors.py", line 181, in __call__
    raise exc
  File "C:\Users\PatCa\anaconda3\lib\site-packages\starlette\middleware\errors.py", line 159, in __call__
    await self.app(scope, receive, _send)
  File "C:\Users\PatCa\anaconda3\lib\site-packages\starlette\exceptions.py", line 82, in __call__
    raise exc
  File "C:\Users\PatCa\anaconda3\lib\site-packages\starlette\exceptions.py", line 71, in __call__
    await self.app(scope, receive, sender)
  File "C:\Users\PatCa\anaconda3\lib\site-packages\starlette\routing.py", line 656, in __call__
    await route.handle(scope, receive, send)
  File "C:\Users\PatCa\anaconda3\lib\site-packages\starlette\routing.py", line 259, in handle
    await self.app(scope, receive, send)
  File "C:\Users\PatCa\anaconda3\lib\site-packages\starlette\routing.py", line 61, in app
    response = await func(request)
  File "C:\Users\PatCa\anaconda3\lib\site-packages\fastapi\routing.py", line 226, in app
    raw_response = await run_endpoint_function(
  File "C:\Users\PatCa\anaconda3\lib\site-packages\fastapi\routing.py", line 159, in run_endpoint_function
    return await dependant.call(**values)
  File ".\app\main.py", line 130, in baby_dashboard
    weight_json = await get_weight()
  File ".\app\data_handler.py", line 19, in get_weight
    w_json = await client.get(adr + "weight")
  File "C:\Users\PatCa\anaconda3\lib\site-packages\httpx\_client.py", line 1704, in get
    return await self.request(
  File "C:\Users\PatCa\anaconda3\lib\site-packages\httpx\_client.py", line 1483, in request
    response = await self.send(
  File "C:\Users\PatCa\anaconda3\lib\site-packages\httpx\_client.py", line 1571, in send
    response = await self._send_handling_auth(
  File "C:\Users\PatCa\anaconda3\lib\site-packages\httpx\_client.py", line 1599, in _send_handling_auth
    response = await self._send_handling_redirects(
  File "C:\Users\PatCa\anaconda3\lib\site-packages\httpx\_client.py", line 1636, in _send_handling_redirects
    response = await self._send_single_request(request)
  File "C:\Users\PatCa\anaconda3\lib\site-packages\httpx\_client.py", line 1673, in _send_single_request
    response = await transport.handle_async_request(request)
  File "C:\Users\PatCa\anaconda3\lib\site-packages\httpx\_transports\default.py", line 271, in handle_async_request
    (
  File "C:\Users\PatCa\anaconda3\lib\contextlib.py", line 131, in __exit__
    self.gen.throw(type, value, traceback)
  File "C:\Users\PatCa\anaconda3\lib\site-packages\httpx\_transports\default.py", line 79, in map_httpcore_exceptions
    raise mapped_exc(message) from exc
httpx.ReadTimeout
2022-01-27 14:43:28,418 INFO     Displaying dashboard
2022-01-27 14:43:39,544 INFO     Updating head data
2022-01-27 14:43:54,585 INFO     Displaying dashboard
2022-01-27 14:44:03,843 INFO     Reset db
2022-01-27 14:44:10,541 INFO     Displaying dashboard
2022-01-27 14:45:11,438 INFO     Reset db
2022-01-27 14:45:26,612 INFO     Displaying dashboard
2022-01-27 14:45:32,112 INFO     Reset db
2022-01-27 14:46:22,800 INFO     Started server process [27284]
2022-01-27 14:46:22,802 INFO     Waiting for application startup.
2022-01-27 14:46:22,803 INFO     Application startup complete.
2022-01-27 14:48:50,239 INFO     Displaying dashboard
2022-01-27 14:54:26,615 INFO     Shutting down
2022-01-27 07:29:33,512 INFO     Started server process [9]
2022-01-27 07:29:33,513 INFO     Waiting for application startup.
2022-01-27 07:29:33,514 INFO     Application startup complete.
2022-01-27 07:42:00,386 INFO     Displaying dashboard
2022-01-27 07:42:13,276 INFO     Displaying dashboard
2022-01-27 07:42:19,245 INFO     Reset db
2022-01-27 07:42:23,061 INFO     Displaying dashboard
2022-01-27 07:42:40,369 INFO     Updating head data
2022-01-27 07:42:53,559 INFO     Displaying dashboard
2022-01-27 07:46:38,766 INFO     Reset db
2022-01-27 07:46:47,088 INFO     Updating head data
2022-01-27 07:46:52,067 INFO     Displaying dashboard
2022-01-27 07:47:16,048 INFO     Updating feeding data
2022-01-27 07:47:24,589 INFO     Displaying dashboard
2022-01-27 07:47:35,735 INFO     Shutting down
2022-01-27 07:47:35,837 INFO     Waiting for application shutdown.
2022-01-27 07:47:35,839 INFO     Application shutdown complete.
2022-01-27 07:47:35,841 INFO     Finished server process [9]
2022-01-27 16:02:20,399 INFO     Started server process [25452]
2022-01-27 16:02:20,423 INFO     Waiting for application startup.
2022-01-27 16:02:20,424 INFO     Application startup complete.
2022-01-27 16:02:38,311 ERROR    Exception in ASGI application
Traceback (most recent call last):
  File "C:\Users\PatCa\anaconda3\lib\site-packages\httpx\_transports\default.py", line 62, in map_httpcore_exceptions
    yield
  File "C:\Users\PatCa\anaconda3\lib\site-packages\httpx\_transports\default.py", line 276, in handle_async_request
    ) = await self._pool.handle_async_request(
  File "C:\Users\PatCa\anaconda3\lib\site-packages\httpcore\_async\connection_pool.py", line 234, in handle_async_request
    response = await connection.handle_async_request(
  File "C:\Users\PatCa\anaconda3\lib\site-packages\httpcore\_async\connection.py", line 136, in handle_async_request
    self.socket = await self._open_socket(timeout)
  File "C:\Users\PatCa\anaconda3\lib\site-packages\httpcore\_async\connection.py", line 163, in _open_socket
    return await self._backend.open_tcp_stream(
  File "C:\Users\PatCa\anaconda3\lib\site-packages\httpcore\_backends\auto.py", line 44, in open_tcp_stream
    return await self.backend.open_tcp_stream(
  File "C:\Users\PatCa\anaconda3\lib\site-packages\httpcore\_backends\anyio.py", line 154, in open_tcp_stream
    stream = await TLSStream.wrap(
  File "C:\Users\PatCa\anaconda3\lib\contextlib.py", line 131, in __exit__
    self.gen.throw(type, value, traceback)
  File "C:\Users\PatCa\anaconda3\lib\site-packages\httpcore\_exceptions.py", line 12, in map_exceptions
    raise to_exc(exc) from None
httpcore.ConnectError: [Errno 11001] getaddrinfo failed

The above exception was the direct cause of the following exception:

Traceback (most recent call last):
  File "C:\Users\PatCa\anaconda3\lib\site-packages\uvicorn\protocols\http\h11_impl.py", line 373, in run_asgi
    result = await app(self.scope, self.receive, self.send)
  File "C:\Users\PatCa\anaconda3\lib\site-packages\uvicorn\middleware\proxy_headers.py", line 75, in __call__
    return await self.app(scope, receive, send)
  File "C:\Users\PatCa\anaconda3\lib\site-packages\fastapi\applications.py", line 208, in __call__
    await super().__call__(scope, receive, send)
  File "C:\Users\PatCa\anaconda3\lib\site-packages\starlette\applications.py", line 112, in __call__
    await self.middleware_stack(scope, receive, send)
  File "C:\Users\PatCa\anaconda3\lib\site-packages\starlette\middleware\errors.py", line 181, in __call__
    raise exc
  File "C:\Users\PatCa\anaconda3\lib\site-packages\starlette\middleware\errors.py", line 159, in __call__
    await self.app(scope, receive, _send)
  File "C:\Users\PatCa\anaconda3\lib\site-packages\starlette\exceptions.py", line 82, in __call__
    raise exc
  File "C:\Users\PatCa\anaconda3\lib\site-packages\starlette\exceptions.py", line 71, in __call__
    await self.app(scope, receive, sender)
  File "C:\Users\PatCa\anaconda3\lib\site-packages\starlette\routing.py", line 656, in __call__
    await route.handle(scope, receive, send)
  File "C:\Users\PatCa\anaconda3\lib\site-packages\starlette\routing.py", line 259, in handle
    await self.app(scope, receive, send)
  File "C:\Users\PatCa\anaconda3\lib\site-packages\starlette\routing.py", line 61, in app
    response = await func(request)
  File "C:\Users\PatCa\anaconda3\lib\site-packages\fastapi\routing.py", line 226, in app
    raw_response = await run_endpoint_function(
  File "C:\Users\PatCa\anaconda3\lib\site-packages\fastapi\routing.py", line 159, in run_endpoint_function
    return await dependant.call(**values)
  File ".\app\main.py", line 130, in baby_dashboard
    weight_json = await get_weight()
  File ".\app\data_handler.py", line 19, in get_weight
    w_json = await client.get(adr + "weight")
  File "C:\Users\PatCa\anaconda3\lib\site-packages\httpx\_client.py", line 1704, in get
    return await self.request(
  File "C:\Users\PatCa\anaconda3\lib\site-packages\httpx\_client.py", line 1483, in request
    response = await self.send(
  File "C:\Users\PatCa\anaconda3\lib\site-packages\httpx\_client.py", line 1571, in send
    response = await self._send_handling_auth(
  File "C:\Users\PatCa\anaconda3\lib\site-packages\httpx\_client.py", line 1599, in _send_handling_auth
    response = await self._send_handling_redirects(
  File "C:\Users\PatCa\anaconda3\lib\site-packages\httpx\_client.py", line 1636, in _send_handling_redirects
    response = await self._send_single_request(request)
  File "C:\Users\PatCa\anaconda3\lib\site-packages\httpx\_client.py", line 1673, in _send_single_request
    response = await transport.handle_async_request(request)
  File "C:\Users\PatCa\anaconda3\lib\site-packages\httpx\_transports\default.py", line 271, in handle_async_request
    (
  File "C:\Users\PatCa\anaconda3\lib\contextlib.py", line 131, in __exit__
    self.gen.throw(type, value, traceback)
  File "C:\Users\PatCa\anaconda3\lib\site-packages\httpx\_transports\default.py", line 79, in map_httpcore_exceptions
    raise mapped_exc(message) from exc
httpx.ConnectError: [Errno 11001] getaddrinfo failed
2022-01-27 16:04:09,532 ERROR    Exception in ASGI application
Traceback (most recent call last):
  File "C:\Users\PatCa\anaconda3\lib\site-packages\httpx\_transports\default.py", line 62, in map_httpcore_exceptions
    yield
  File "C:\Users\PatCa\anaconda3\lib\site-packages\httpx\_transports\default.py", line 276, in handle_async_request
    ) = await self._pool.handle_async_request(
  File "C:\Users\PatCa\anaconda3\lib\site-packages\httpcore\_async\connection_pool.py", line 234, in handle_async_request
    response = await connection.handle_async_request(
  File "C:\Users\PatCa\anaconda3\lib\site-packages\httpcore\_async\connection.py", line 136, in handle_async_request
    self.socket = await self._open_socket(timeout)
  File "C:\Users\PatCa\anaconda3\lib\site-packages\httpcore\_async\connection.py", line 163, in _open_socket
    return await self._backend.open_tcp_stream(
  File "C:\Users\PatCa\anaconda3\lib\site-packages\httpcore\_backends\auto.py", line 44, in open_tcp_stream
    return await self.backend.open_tcp_stream(
  File "C:\Users\PatCa\anaconda3\lib\site-packages\httpcore\_backends\anyio.py", line 154, in open_tcp_stream
    stream = await TLSStream.wrap(
  File "C:\Users\PatCa\anaconda3\lib\contextlib.py", line 131, in __exit__
    self.gen.throw(type, value, traceback)
  File "C:\Users\PatCa\anaconda3\lib\site-packages\httpcore\_exceptions.py", line 12, in map_exceptions
    raise to_exc(exc) from None
httpcore.ConnectError: [Errno 11001] getaddrinfo failed

The above exception was the direct cause of the following exception:

Traceback (most recent call last):
  File "C:\Users\PatCa\anaconda3\lib\site-packages\uvicorn\protocols\http\h11_impl.py", line 373, in run_asgi
    result = await app(self.scope, self.receive, self.send)
  File "C:\Users\PatCa\anaconda3\lib\site-packages\uvicorn\middleware\proxy_headers.py", line 75, in __call__
    return await self.app(scope, receive, send)
  File "C:\Users\PatCa\anaconda3\lib\site-packages\fastapi\applications.py", line 208, in __call__
    await super().__call__(scope, receive, send)
  File "C:\Users\PatCa\anaconda3\lib\site-packages\starlette\applications.py", line 112, in __call__
    await self.middleware_stack(scope, receive, send)
  File "C:\Users\PatCa\anaconda3\lib\site-packages\starlette\middleware\errors.py", line 181, in __call__
    raise exc
  File "C:\Users\PatCa\anaconda3\lib\site-packages\starlette\middleware\errors.py", line 159, in __call__
    await self.app(scope, receive, _send)
  File "C:\Users\PatCa\anaconda3\lib\site-packages\starlette\exceptions.py", line 82, in __call__
    raise exc
  File "C:\Users\PatCa\anaconda3\lib\site-packages\starlette\exceptions.py", line 71, in __call__
    await self.app(scope, receive, sender)
  File "C:\Users\PatCa\anaconda3\lib\site-packages\starlette\routing.py", line 656, in __call__
    await route.handle(scope, receive, send)
  File "C:\Users\PatCa\anaconda3\lib\site-packages\starlette\routing.py", line 259, in handle
    await self.app(scope, receive, send)
  File "C:\Users\PatCa\anaconda3\lib\site-packages\starlette\routing.py", line 61, in app
    response = await func(request)
  File "C:\Users\PatCa\anaconda3\lib\site-packages\fastapi\routing.py", line 226, in app
    raw_response = await run_endpoint_function(
  File "C:\Users\PatCa\anaconda3\lib\site-packages\fastapi\routing.py", line 159, in run_endpoint_function
    return await dependant.call(**values)
  File ".\app\main.py", line 130, in baby_dashboard
    weight_json = await get_weight()
  File ".\app\data_handler.py", line 19, in get_weight
    w_json = await client.get(adr + "weight")
  File "C:\Users\PatCa\anaconda3\lib\site-packages\httpx\_client.py", line 1704, in get
    return await self.request(
  File "C:\Users\PatCa\anaconda3\lib\site-packages\httpx\_client.py", line 1483, in request
    response = await self.send(
  File "C:\Users\PatCa\anaconda3\lib\site-packages\httpx\_client.py", line 1571, in send
    response = await self._send_handling_auth(
  File "C:\Users\PatCa\anaconda3\lib\site-packages\httpx\_client.py", line 1599, in _send_handling_auth
    response = await self._send_handling_redirects(
  File "C:\Users\PatCa\anaconda3\lib\site-packages\httpx\_client.py", line 1636, in _send_handling_redirects
    response = await self._send_single_request(request)
  File "C:\Users\PatCa\anaconda3\lib\site-packages\httpx\_client.py", line 1673, in _send_single_request
    response = await transport.handle_async_request(request)
  File "C:\Users\PatCa\anaconda3\lib\site-packages\httpx\_transports\default.py", line 271, in handle_async_request
    (
  File "C:\Users\PatCa\anaconda3\lib\contextlib.py", line 131, in __exit__
    self.gen.throw(type, value, traceback)
  File "C:\Users\PatCa\anaconda3\lib\site-packages\httpx\_transports\default.py", line 79, in map_httpcore_exceptions
    raise mapped_exc(message) from exc
httpx.ConnectError: [Errno 11001] getaddrinfo failed
2022-01-27 16:04:52,731 ERROR    Exception in ASGI application
Traceback (most recent call last):
  File "C:\Users\PatCa\anaconda3\lib\site-packages\httpx\_transports\default.py", line 62, in map_httpcore_exceptions
    yield
  File "C:\Users\PatCa\anaconda3\lib\site-packages\httpx\_transports\default.py", line 276, in handle_async_request
    ) = await self._pool.handle_async_request(
  File "C:\Users\PatCa\anaconda3\lib\site-packages\httpcore\_async\connection_pool.py", line 234, in handle_async_request
    response = await connection.handle_async_request(
  File "C:\Users\PatCa\anaconda3\lib\site-packages\httpcore\_async\connection.py", line 136, in handle_async_request
    self.socket = await self._open_socket(timeout)
  File "C:\Users\PatCa\anaconda3\lib\site-packages\httpcore\_async\connection.py", line 163, in _open_socket
    return await self._backend.open_tcp_stream(
  File "C:\Users\PatCa\anaconda3\lib\site-packages\httpcore\_backends\auto.py", line 44, in open_tcp_stream
    return await self.backend.open_tcp_stream(
  File "C:\Users\PatCa\anaconda3\lib\site-packages\httpcore\_backends\anyio.py", line 154, in open_tcp_stream
    stream = await TLSStream.wrap(
  File "C:\Users\PatCa\anaconda3\lib\contextlib.py", line 131, in __exit__
    self.gen.throw(type, value, traceback)
  File "C:\Users\PatCa\anaconda3\lib\site-packages\httpcore\_exceptions.py", line 12, in map_exceptions
    raise to_exc(exc) from None
httpcore.ConnectError: [Errno 11001] getaddrinfo failed

The above exception was the direct cause of the following exception:

Traceback (most recent call last):
  File "C:\Users\PatCa\anaconda3\lib\site-packages\uvicorn\protocols\http\h11_impl.py", line 373, in run_asgi
    result = await app(self.scope, self.receive, self.send)
  File "C:\Users\PatCa\anaconda3\lib\site-packages\uvicorn\middleware\proxy_headers.py", line 75, in __call__
    return await self.app(scope, receive, send)
  File "C:\Users\PatCa\anaconda3\lib\site-packages\fastapi\applications.py", line 208, in __call__
    await super().__call__(scope, receive, send)
  File "C:\Users\PatCa\anaconda3\lib\site-packages\starlette\applications.py", line 112, in __call__
    await self.middleware_stack(scope, receive, send)
  File "C:\Users\PatCa\anaconda3\lib\site-packages\starlette\middleware\errors.py", line 181, in __call__
    raise exc
  File "C:\Users\PatCa\anaconda3\lib\site-packages\starlette\middleware\errors.py", line 159, in __call__
    await self.app(scope, receive, _send)
  File "C:\Users\PatCa\anaconda3\lib\site-packages\starlette\exceptions.py", line 82, in __call__
    raise exc
  File "C:\Users\PatCa\anaconda3\lib\site-packages\starlette\exceptions.py", line 71, in __call__
    await self.app(scope, receive, sender)
  File "C:\Users\PatCa\anaconda3\lib\site-packages\starlette\routing.py", line 656, in __call__
    await route.handle(scope, receive, send)
  File "C:\Users\PatCa\anaconda3\lib\site-packages\starlette\routing.py", line 259, in handle
    await self.app(scope, receive, send)
  File "C:\Users\PatCa\anaconda3\lib\site-packages\starlette\routing.py", line 61, in app
    response = await func(request)
  File "C:\Users\PatCa\anaconda3\lib\site-packages\fastapi\routing.py", line 226, in app
    raw_response = await run_endpoint_function(
  File "C:\Users\PatCa\anaconda3\lib\site-packages\fastapi\routing.py", line 159, in run_endpoint_function
    return await dependant.call(**values)
  File ".\app\main.py", line 57, in baby_weight
    weight_json = await get_weight()
  File ".\app\data_handler.py", line 19, in get_weight
    w_json = await client.get(adr + "weight")
  File "C:\Users\PatCa\anaconda3\lib\site-packages\httpx\_client.py", line 1704, in get
    return await self.request(
  File "C:\Users\PatCa\anaconda3\lib\site-packages\httpx\_client.py", line 1483, in request
    response = await self.send(
  File "C:\Users\PatCa\anaconda3\lib\site-packages\httpx\_client.py", line 1571, in send
    response = await self._send_handling_auth(
  File "C:\Users\PatCa\anaconda3\lib\site-packages\httpx\_client.py", line 1599, in _send_handling_auth
    response = await self._send_handling_redirects(
  File "C:\Users\PatCa\anaconda3\lib\site-packages\httpx\_client.py", line 1636, in _send_handling_redirects
    response = await self._send_single_request(request)
  File "C:\Users\PatCa\anaconda3\lib\site-packages\httpx\_client.py", line 1673, in _send_single_request
    response = await transport.handle_async_request(request)
  File "C:\Users\PatCa\anaconda3\lib\site-packages\httpx\_transports\default.py", line 271, in handle_async_request
    (
  File "C:\Users\PatCa\anaconda3\lib\contextlib.py", line 131, in __exit__
    self.gen.throw(type, value, traceback)
  File "C:\Users\PatCa\anaconda3\lib\site-packages\httpx\_transports\default.py", line 79, in map_httpcore_exceptions
    raise mapped_exc(message) from exc
httpx.ConnectError: [Errno 11001] getaddrinfo failed
2022-01-27 16:05:49,306 INFO     Started server process [30960]
2022-01-27 16:05:49,306 INFO     Waiting for application startup.
2022-01-27 16:05:49,307 INFO     Application startup complete.
2022-01-27 16:05:57,136 ERROR    Exception in ASGI application
Traceback (most recent call last):
  File "C:\Users\PatCa\anaconda3\lib\site-packages\httpx\_transports\default.py", line 62, in map_httpcore_exceptions
    yield
  File "C:\Users\PatCa\anaconda3\lib\site-packages\httpx\_transports\default.py", line 276, in handle_async_request
    ) = await self._pool.handle_async_request(
  File "C:\Users\PatCa\anaconda3\lib\site-packages\httpcore\_async\connection_pool.py", line 234, in handle_async_request
    response = await connection.handle_async_request(
  File "C:\Users\PatCa\anaconda3\lib\site-packages\httpcore\_async\connection.py", line 136, in handle_async_request
    self.socket = await self._open_socket(timeout)
  File "C:\Users\PatCa\anaconda3\lib\site-packages\httpcore\_async\connection.py", line 163, in _open_socket
    return await self._backend.open_tcp_stream(
  File "C:\Users\PatCa\anaconda3\lib\site-packages\httpcore\_backends\auto.py", line 44, in open_tcp_stream
    return await self.backend.open_tcp_stream(
  File "C:\Users\PatCa\anaconda3\lib\site-packages\httpcore\_backends\anyio.py", line 154, in open_tcp_stream
    stream = await TLSStream.wrap(
  File "C:\Users\PatCa\anaconda3\lib\contextlib.py", line 131, in __exit__
    self.gen.throw(type, value, traceback)
  File "C:\Users\PatCa\anaconda3\lib\site-packages\httpcore\_exceptions.py", line 12, in map_exceptions
    raise to_exc(exc) from None
httpcore.ConnectError: All connection attempts failed

The above exception was the direct cause of the following exception:

Traceback (most recent call last):
  File "C:\Users\PatCa\anaconda3\lib\site-packages\uvicorn\protocols\http\h11_impl.py", line 373, in run_asgi
    result = await app(self.scope, self.receive, self.send)
  File "C:\Users\PatCa\anaconda3\lib\site-packages\uvicorn\middleware\proxy_headers.py", line 75, in __call__
    return await self.app(scope, receive, send)
  File "C:\Users\PatCa\anaconda3\lib\site-packages\fastapi\applications.py", line 208, in __call__
    await super().__call__(scope, receive, send)
  File "C:\Users\PatCa\anaconda3\lib\site-packages\starlette\applications.py", line 112, in __call__
    await self.middleware_stack(scope, receive, send)
  File "C:\Users\PatCa\anaconda3\lib\site-packages\starlette\middleware\errors.py", line 181, in __call__
    raise exc
  File "C:\Users\PatCa\anaconda3\lib\site-packages\starlette\middleware\errors.py", line 159, in __call__
    await self.app(scope, receive, _send)
  File "C:\Users\PatCa\anaconda3\lib\site-packages\starlette\exceptions.py", line 82, in __call__
    raise exc
  File "C:\Users\PatCa\anaconda3\lib\site-packages\starlette\exceptions.py", line 71, in __call__
    await self.app(scope, receive, sender)
  File "C:\Users\PatCa\anaconda3\lib\site-packages\starlette\routing.py", line 656, in __call__
    await route.handle(scope, receive, send)
  File "C:\Users\PatCa\anaconda3\lib\site-packages\starlette\routing.py", line 259, in handle
    await self.app(scope, receive, send)
  File "C:\Users\PatCa\anaconda3\lib\site-packages\starlette\routing.py", line 61, in app
    response = await func(request)
  File "C:\Users\PatCa\anaconda3\lib\site-packages\fastapi\routing.py", line 226, in app
    raw_response = await run_endpoint_function(
  File "C:\Users\PatCa\anaconda3\lib\site-packages\fastapi\routing.py", line 159, in run_endpoint_function
    return await dependant.call(**values)
  File ".\app\main.py", line 57, in baby_weight
    weight_json = await get_weight()
  File ".\app\data_handler.py", line 19, in get_weight
    w_json = await client.get(adr + "weight")
  File "C:\Users\PatCa\anaconda3\lib\site-packages\httpx\_client.py", line 1704, in get
    return await self.request(
  File "C:\Users\PatCa\anaconda3\lib\site-packages\httpx\_client.py", line 1483, in request
    response = await self.send(
  File "C:\Users\PatCa\anaconda3\lib\site-packages\httpx\_client.py", line 1571, in send
    response = await self._send_handling_auth(
  File "C:\Users\PatCa\anaconda3\lib\site-packages\httpx\_client.py", line 1599, in _send_handling_auth
    response = await self._send_handling_redirects(
  File "C:\Users\PatCa\anaconda3\lib\site-packages\httpx\_client.py", line 1636, in _send_handling_redirects
    response = await self._send_single_request(request)
  File "C:\Users\PatCa\anaconda3\lib\site-packages\httpx\_client.py", line 1673, in _send_single_request
    response = await transport.handle_async_request(request)
  File "C:\Users\PatCa\anaconda3\lib\site-packages\httpx\_transports\default.py", line 271, in handle_async_request
    (
  File "C:\Users\PatCa\anaconda3\lib\contextlib.py", line 131, in __exit__
    self.gen.throw(type, value, traceback)
  File "C:\Users\PatCa\anaconda3\lib\site-packages\httpx\_transports\default.py", line 79, in map_httpcore_exceptions
    raise mapped_exc(message) from exc
httpx.ConnectError: All connection attempts failed
2022-01-27 16:07:19,543 INFO     Displaying dashboard
2022-01-27 16:07:47,431 INFO     Updating head data
2022-01-27 16:07:52,594 INFO     Displaying dashboard
2022-01-27 16:14:49,467 INFO     Updating head data
2022-01-27 16:15:02,664 INFO     Displaying dashboard
2022-01-27 16:15:54,309 INFO     Started server process [28880]
2022-01-27 16:15:54,310 INFO     Waiting for application startup.
2022-01-27 16:15:54,311 INFO     Application startup complete.
2022-01-27 16:16:12,609 INFO     Started server process [28660]
2022-01-27 16:16:12,609 INFO     Waiting for application startup.
2022-01-27 16:16:12,609 INFO     Application startup complete.
2022-01-27 16:16:31,993 INFO     Updating head data
2022-01-27 16:16:43,333 INFO     Displaying dashboard
2022-01-27 16:16:53,225 INFO     Reset db
2022-01-27 16:16:57,014 INFO     Displaying dashboard
2022-01-27 08:17:32,500 INFO     Started server process [9]
2022-01-27 08:17:32,500 INFO     Waiting for application startup.
2022-01-27 08:17:32,501 INFO     Application startup complete.
2022-01-27 08:20:36,085 INFO     Shutting down
2022-01-27 08:20:36,186 INFO     Waiting for application shutdown.
2022-01-27 08:20:36,188 INFO     Application shutdown complete.
2022-01-27 08:20:36,190 INFO     Finished server process [9]
2022-01-27 08:22:26,897 INFO     Started server process [9]
2022-01-27 08:22:26,897 INFO     Waiting for application startup.
2022-01-27 08:22:26,898 INFO     Application startup complete.
2022-01-27 16:22:51,507 INFO     Displaying dashboard
2022-01-27 16:23:05,413 INFO     Updating head data
2022-01-27 16:23:08,676 INFO     Displaying dashboard
2022-01-27 08:28:40,107 INFO     Shutting down
2022-01-27 08:28:40,208 INFO     Waiting for application shutdown.
2022-01-27 08:28:40,209 INFO     Application shutdown complete.
2022-01-27 08:28:40,209 INFO     Finished server process [9]
2022-01-27 16:28:42,985 INFO     Started server process [29936]
2022-01-27 16:28:42,988 INFO     Waiting for application startup.
2022-01-27 16:28:42,989 INFO     Application startup complete.
2022-01-27 08:28:44,033 INFO     Started server process [20]
2022-01-27 08:28:44,034 INFO     Waiting for application startup.
2022-01-27 08:28:44,035 INFO     Application startup complete.
2022-01-27 16:28:53,571 ERROR    Exception in ASGI application
Traceback (most recent call last):
  File "C:\Users\PatCa\anaconda3\lib\site-packages\httpx\_transports\default.py", line 62, in map_httpcore_exceptions
    yield
  File "C:\Users\PatCa\anaconda3\lib\site-packages\httpx\_transports\default.py", line 276, in handle_async_request
    ) = await self._pool.handle_async_request(
  File "C:\Users\PatCa\anaconda3\lib\site-packages\httpcore\_async\connection_pool.py", line 234, in handle_async_request
    response = await connection.handle_async_request(
  File "C:\Users\PatCa\anaconda3\lib\site-packages\httpcore\_async\connection.py", line 136, in handle_async_request
    self.socket = await self._open_socket(timeout)
  File "C:\Users\PatCa\anaconda3\lib\site-packages\httpcore\_async\connection.py", line 163, in _open_socket
    return await self._backend.open_tcp_stream(
  File "C:\Users\PatCa\anaconda3\lib\site-packages\httpcore\_backends\auto.py", line 44, in open_tcp_stream
    return await self.backend.open_tcp_stream(
  File "C:\Users\PatCa\anaconda3\lib\site-packages\httpcore\_backends\anyio.py", line 154, in open_tcp_stream
    stream = await TLSStream.wrap(
  File "C:\Users\PatCa\anaconda3\lib\contextlib.py", line 131, in __exit__
    self.gen.throw(type, value, traceback)
  File "C:\Users\PatCa\anaconda3\lib\site-packages\httpcore\_exceptions.py", line 12, in map_exceptions
    raise to_exc(exc) from None
httpcore.ConnectError: [Errno 11001] getaddrinfo failed

The above exception was the direct cause of the following exception:

Traceback (most recent call last):
  File "C:\Users\PatCa\anaconda3\lib\site-packages\uvicorn\protocols\http\h11_impl.py", line 373, in run_asgi
    result = await app(self.scope, self.receive, self.send)
  File "C:\Users\PatCa\anaconda3\lib\site-packages\uvicorn\middleware\proxy_headers.py", line 75, in __call__
    return await self.app(scope, receive, send)
  File "C:\Users\PatCa\anaconda3\lib\site-packages\fastapi\applications.py", line 208, in __call__
    await super().__call__(scope, receive, send)
  File "C:\Users\PatCa\anaconda3\lib\site-packages\starlette\applications.py", line 112, in __call__
    await self.middleware_stack(scope, receive, send)
  File "C:\Users\PatCa\anaconda3\lib\site-packages\starlette\middleware\errors.py", line 181, in __call__
    raise exc
  File "C:\Users\PatCa\anaconda3\lib\site-packages\starlette\middleware\errors.py", line 159, in __call__
    await self.app(scope, receive, _send)
  File "C:\Users\PatCa\anaconda3\lib\site-packages\starlette\exceptions.py", line 82, in __call__
    raise exc
  File "C:\Users\PatCa\anaconda3\lib\site-packages\starlette\exceptions.py", line 71, in __call__
    await self.app(scope, receive, sender)
  File "C:\Users\PatCa\anaconda3\lib\site-packages\starlette\routing.py", line 656, in __call__
    await route.handle(scope, receive, send)
  File "C:\Users\PatCa\anaconda3\lib\site-packages\starlette\routing.py", line 259, in handle
    await self.app(scope, receive, send)
  File "C:\Users\PatCa\anaconda3\lib\site-packages\starlette\routing.py", line 61, in app
    response = await func(request)
  File "C:\Users\PatCa\anaconda3\lib\site-packages\fastapi\routing.py", line 226, in app
    raw_response = await run_endpoint_function(
  File "C:\Users\PatCa\anaconda3\lib\site-packages\fastapi\routing.py", line 159, in run_endpoint_function
    return await dependant.call(**values)
  File ".\app\main.py", line 130, in baby_dashboard
    weight_json = await get_weight()
  File ".\app\data_handler.py", line 19, in get_weight
    w_json = await client.get(adr + "weight")
  File "C:\Users\PatCa\anaconda3\lib\site-packages\httpx\_client.py", line 1704, in get
    return await self.request(
  File "C:\Users\PatCa\anaconda3\lib\site-packages\httpx\_client.py", line 1483, in request
    response = await self.send(
  File "C:\Users\PatCa\anaconda3\lib\site-packages\httpx\_client.py", line 1571, in send
    response = await self._send_handling_auth(
  File "C:\Users\PatCa\anaconda3\lib\site-packages\httpx\_client.py", line 1599, in _send_handling_auth
    response = await self._send_handling_redirects(
  File "C:\Users\PatCa\anaconda3\lib\site-packages\httpx\_client.py", line 1636, in _send_handling_redirects
    response = await self._send_single_request(request)
  File "C:\Users\PatCa\anaconda3\lib\site-packages\httpx\_client.py", line 1673, in _send_single_request
    response = await transport.handle_async_request(request)
  File "C:\Users\PatCa\anaconda3\lib\site-packages\httpx\_transports\default.py", line 271, in handle_async_request
    (
  File "C:\Users\PatCa\anaconda3\lib\contextlib.py", line 131, in __exit__
    self.gen.throw(type, value, traceback)
  File "C:\Users\PatCa\anaconda3\lib\site-packages\httpx\_transports\default.py", line 79, in map_httpcore_exceptions
    raise mapped_exc(message) from exc
httpx.ConnectError: [Errno 11001] getaddrinfo failed
2022-01-27 16:29:00,229 ERROR    Exception in ASGI application
Traceback (most recent call last):
  File "C:\Users\PatCa\anaconda3\lib\site-packages\httpx\_transports\default.py", line 62, in map_httpcore_exceptions
    yield
  File "C:\Users\PatCa\anaconda3\lib\site-packages\httpx\_transports\default.py", line 276, in handle_async_request
    ) = await self._pool.handle_async_request(
  File "C:\Users\PatCa\anaconda3\lib\site-packages\httpcore\_async\connection_pool.py", line 234, in handle_async_request
    response = await connection.handle_async_request(
  File "C:\Users\PatCa\anaconda3\lib\site-packages\httpcore\_async\connection.py", line 136, in handle_async_request
    self.socket = await self._open_socket(timeout)
  File "C:\Users\PatCa\anaconda3\lib\site-packages\httpcore\_async\connection.py", line 163, in _open_socket
    return await self._backend.open_tcp_stream(
  File "C:\Users\PatCa\anaconda3\lib\site-packages\httpcore\_backends\auto.py", line 44, in open_tcp_stream
    return await self.backend.open_tcp_stream(
  File "C:\Users\PatCa\anaconda3\lib\site-packages\httpcore\_backends\anyio.py", line 154, in open_tcp_stream
    stream = await TLSStream.wrap(
  File "C:\Users\PatCa\anaconda3\lib\contextlib.py", line 131, in __exit__
    self.gen.throw(type, value, traceback)
  File "C:\Users\PatCa\anaconda3\lib\site-packages\httpcore\_exceptions.py", line 12, in map_exceptions
    raise to_exc(exc) from None
httpcore.ConnectError: [Errno 11001] getaddrinfo failed

The above exception was the direct cause of the following exception:

Traceback (most recent call last):
  File "C:\Users\PatCa\anaconda3\lib\site-packages\uvicorn\protocols\http\h11_impl.py", line 373, in run_asgi
    result = await app(self.scope, self.receive, self.send)
  File "C:\Users\PatCa\anaconda3\lib\site-packages\uvicorn\middleware\proxy_headers.py", line 75, in __call__
    return await self.app(scope, receive, send)
  File "C:\Users\PatCa\anaconda3\lib\site-packages\fastapi\applications.py", line 208, in __call__
    await super().__call__(scope, receive, send)
  File "C:\Users\PatCa\anaconda3\lib\site-packages\starlette\applications.py", line 112, in __call__
    await self.middleware_stack(scope, receive, send)
  File "C:\Users\PatCa\anaconda3\lib\site-packages\starlette\middleware\errors.py", line 181, in __call__
    raise exc
  File "C:\Users\PatCa\anaconda3\lib\site-packages\starlette\middleware\errors.py", line 159, in __call__
    await self.app(scope, receive, _send)
  File "C:\Users\PatCa\anaconda3\lib\site-packages\starlette\exceptions.py", line 82, in __call__
    raise exc
  File "C:\Users\PatCa\anaconda3\lib\site-packages\starlette\exceptions.py", line 71, in __call__
    await self.app(scope, receive, sender)
  File "C:\Users\PatCa\anaconda3\lib\site-packages\starlette\routing.py", line 656, in __call__
    await route.handle(scope, receive, send)
  File "C:\Users\PatCa\anaconda3\lib\site-packages\starlette\routing.py", line 259, in handle
    await self.app(scope, receive, send)
  File "C:\Users\PatCa\anaconda3\lib\site-packages\starlette\routing.py", line 61, in app
    response = await func(request)
  File "C:\Users\PatCa\anaconda3\lib\site-packages\fastapi\routing.py", line 226, in app
    raw_response = await run_endpoint_function(
  File "C:\Users\PatCa\anaconda3\lib\site-packages\fastapi\routing.py", line 159, in run_endpoint_function
    return await dependant.call(**values)
  File ".\app\main.py", line 130, in baby_dashboard
    weight_json = await get_weight()
  File ".\app\data_handler.py", line 19, in get_weight
    w_json = await client.get(adr + "weight")
  File "C:\Users\PatCa\anaconda3\lib\site-packages\httpx\_client.py", line 1704, in get
    return await self.request(
  File "C:\Users\PatCa\anaconda3\lib\site-packages\httpx\_client.py", line 1483, in request
    response = await self.send(
  File "C:\Users\PatCa\anaconda3\lib\site-packages\httpx\_client.py", line 1571, in send
    response = await self._send_handling_auth(
  File "C:\Users\PatCa\anaconda3\lib\site-packages\httpx\_client.py", line 1599, in _send_handling_auth
    response = await self._send_handling_redirects(
  File "C:\Users\PatCa\anaconda3\lib\site-packages\httpx\_client.py", line 1636, in _send_handling_redirects
    response = await self._send_single_request(request)
  File "C:\Users\PatCa\anaconda3\lib\site-packages\httpx\_client.py", line 1673, in _send_single_request
    response = await transport.handle_async_request(request)
  File "C:\Users\PatCa\anaconda3\lib\site-packages\httpx\_transports\default.py", line 271, in handle_async_request
    (
  File "C:\Users\PatCa\anaconda3\lib\contextlib.py", line 131, in __exit__
    self.gen.throw(type, value, traceback)
  File "C:\Users\PatCa\anaconda3\lib\site-packages\httpx\_transports\default.py", line 79, in map_httpcore_exceptions
    raise mapped_exc(message) from exc
httpx.ConnectError: [Errno 11001] getaddrinfo failed
2022-01-27 16:29:14,899 INFO     Shutting down
2022-01-27 16:29:15,006 INFO     Waiting for application shutdown.
2022-01-27 16:29:15,007 INFO     Application shutdown complete.
2022-01-27 16:29:15,007 INFO     Finished server process [29936]
2022-01-27 08:29:42,637 INFO     Shutting down
2022-01-27 08:29:42,739 INFO     Waiting for application shutdown.
2022-01-27 08:29:42,740 INFO     Application shutdown complete.
2022-01-27 08:29:42,741 INFO     Finished server process [20]
2022-01-27 08:30:00,895 INFO     Started server process [8]
2022-01-27 08:30:00,896 INFO     Waiting for application startup.
2022-01-27 08:30:00,897 INFO     Application startup complete.
2022-01-27 08:30:24,730 INFO     Displaying dashboard
2022-01-27 08:30:41,619 INFO     Shutting down
2022-01-27 08:30:41,720 INFO     Waiting for application shutdown.
2022-01-27 08:30:41,721 INFO     Application shutdown complete.
2022-01-27 08:30:41,722 INFO     Finished server process [8]
2022-01-27 08:31:01,385 INFO     Started server process [9]
2022-01-27 08:31:01,386 INFO     Waiting for application startup.
2022-01-27 08:31:01,387 INFO     Application startup complete.
2022-01-27 08:31:07,957 INFO     Displaying dashboard
2022-01-27 08:31:13,201 INFO     Shutting down
2022-01-27 08:31:13,302 INFO     Waiting for application shutdown.
2022-01-27 08:31:13,303 INFO     Application shutdown complete.
2022-01-27 08:31:13,304 INFO     Finished server process [9]
2022-01-27 08:33:07,512 INFO     Started server process [9]
2022-01-27 08:33:07,513 INFO     Waiting for application startup.
2022-01-27 08:33:07,514 INFO     Application startup complete.
2022-01-27 08:33:20,563 INFO     Displaying dashboard
2022-01-27 08:33:28,618 INFO     Shutting down
2022-01-27 08:33:28,719 INFO     Waiting for application shutdown.
2022-01-27 08:33:28,720 INFO     Application shutdown complete.
2022-01-27 08:33:28,721 INFO     Finished server process [9]
2022-01-27 16:34:05,337 INFO     Started server process [25792]
2022-01-27 16:34:05,337 INFO     Waiting for application startup.
2022-01-27 16:34:05,342 INFO     Application startup complete.
2022-01-27 16:34:20,600 ERROR    Exception in ASGI application
Traceback (most recent call last):
  File "C:\Users\PatCa\anaconda3\lib\site-packages\httpx\_transports\default.py", line 62, in map_httpcore_exceptions
    yield
  File "C:\Users\PatCa\anaconda3\lib\site-packages\httpx\_transports\default.py", line 276, in handle_async_request
    ) = await self._pool.handle_async_request(
  File "C:\Users\PatCa\anaconda3\lib\site-packages\httpcore\_async\connection_pool.py", line 234, in handle_async_request
    response = await connection.handle_async_request(
  File "C:\Users\PatCa\anaconda3\lib\site-packages\httpcore\_async\connection.py", line 136, in handle_async_request
    self.socket = await self._open_socket(timeout)
  File "C:\Users\PatCa\anaconda3\lib\site-packages\httpcore\_async\connection.py", line 163, in _open_socket
    return await self._backend.open_tcp_stream(
  File "C:\Users\PatCa\anaconda3\lib\site-packages\httpcore\_backends\auto.py", line 44, in open_tcp_stream
    return await self.backend.open_tcp_stream(
  File "C:\Users\PatCa\anaconda3\lib\site-packages\httpcore\_backends\anyio.py", line 154, in open_tcp_stream
    stream = await TLSStream.wrap(
  File "C:\Users\PatCa\anaconda3\lib\contextlib.py", line 131, in __exit__
    self.gen.throw(type, value, traceback)
  File "C:\Users\PatCa\anaconda3\lib\site-packages\httpcore\_exceptions.py", line 12, in map_exceptions
    raise to_exc(exc) from None
httpcore.ConnectError: [Errno 11001] getaddrinfo failed

The above exception was the direct cause of the following exception:

Traceback (most recent call last):
  File "C:\Users\PatCa\anaconda3\lib\site-packages\uvicorn\protocols\http\h11_impl.py", line 373, in run_asgi
    result = await app(self.scope, self.receive, self.send)
  File "C:\Users\PatCa\anaconda3\lib\site-packages\uvicorn\middleware\proxy_headers.py", line 75, in __call__
    return await self.app(scope, receive, send)
  File "C:\Users\PatCa\anaconda3\lib\site-packages\fastapi\applications.py", line 208, in __call__
    await super().__call__(scope, receive, send)
  File "C:\Users\PatCa\anaconda3\lib\site-packages\starlette\applications.py", line 112, in __call__
    await self.middleware_stack(scope, receive, send)
  File "C:\Users\PatCa\anaconda3\lib\site-packages\starlette\middleware\errors.py", line 181, in __call__
    raise exc
  File "C:\Users\PatCa\anaconda3\lib\site-packages\starlette\middleware\errors.py", line 159, in __call__
    await self.app(scope, receive, _send)
  File "C:\Users\PatCa\anaconda3\lib\site-packages\starlette\exceptions.py", line 82, in __call__
    raise exc
  File "C:\Users\PatCa\anaconda3\lib\site-packages\starlette\exceptions.py", line 71, in __call__
    await self.app(scope, receive, sender)
  File "C:\Users\PatCa\anaconda3\lib\site-packages\starlette\routing.py", line 656, in __call__
    await route.handle(scope, receive, send)
  File "C:\Users\PatCa\anaconda3\lib\site-packages\starlette\routing.py", line 259, in handle
    await self.app(scope, receive, send)
  File "C:\Users\PatCa\anaconda3\lib\site-packages\starlette\routing.py", line 61, in app
    response = await func(request)
  File "C:\Users\PatCa\anaconda3\lib\site-packages\fastapi\routing.py", line 226, in app
    raw_response = await run_endpoint_function(
  File "C:\Users\PatCa\anaconda3\lib\site-packages\fastapi\routing.py", line 159, in run_endpoint_function
    return await dependant.call(**values)
  File ".\app\main.py", line 130, in baby_dashboard
    weight_json = await get_weight()
  File ".\app\data_handler.py", line 19, in get_weight
    w_json = await client.get(adr + "weight")
  File "C:\Users\PatCa\anaconda3\lib\site-packages\httpx\_client.py", line 1704, in get
    return await self.request(
  File "C:\Users\PatCa\anaconda3\lib\site-packages\httpx\_client.py", line 1483, in request
    response = await self.send(
  File "C:\Users\PatCa\anaconda3\lib\site-packages\httpx\_client.py", line 1571, in send
    response = await self._send_handling_auth(
  File "C:\Users\PatCa\anaconda3\lib\site-packages\httpx\_client.py", line 1599, in _send_handling_auth
    response = await self._send_handling_redirects(
  File "C:\Users\PatCa\anaconda3\lib\site-packages\httpx\_client.py", line 1636, in _send_handling_redirects
    response = await self._send_single_request(request)
  File "C:\Users\PatCa\anaconda3\lib\site-packages\httpx\_client.py", line 1673, in _send_single_request
    response = await transport.handle_async_request(request)
  File "C:\Users\PatCa\anaconda3\lib\site-packages\httpx\_transports\default.py", line 271, in handle_async_request
    (
  File "C:\Users\PatCa\anaconda3\lib\contextlib.py", line 131, in __exit__
    self.gen.throw(type, value, traceback)
  File "C:\Users\PatCa\anaconda3\lib\site-packages\httpx\_transports\default.py", line 79, in map_httpcore_exceptions
    raise mapped_exc(message) from exc
httpx.ConnectError: [Errno 11001] getaddrinfo failed
2022-01-27 16:35:08,934 ERROR    Exception in ASGI application
Traceback (most recent call last):
  File "C:\Users\PatCa\anaconda3\lib\site-packages\httpx\_transports\default.py", line 62, in map_httpcore_exceptions
    yield
  File "C:\Users\PatCa\anaconda3\lib\site-packages\httpx\_transports\default.py", line 276, in handle_async_request
    ) = await self._pool.handle_async_request(
  File "C:\Users\PatCa\anaconda3\lib\site-packages\httpcore\_async\connection_pool.py", line 234, in handle_async_request
    response = await connection.handle_async_request(
  File "C:\Users\PatCa\anaconda3\lib\site-packages\httpcore\_async\connection.py", line 136, in handle_async_request
    self.socket = await self._open_socket(timeout)
  File "C:\Users\PatCa\anaconda3\lib\site-packages\httpcore\_async\connection.py", line 163, in _open_socket
    return await self._backend.open_tcp_stream(
  File "C:\Users\PatCa\anaconda3\lib\site-packages\httpcore\_backends\auto.py", line 44, in open_tcp_stream
    return await self.backend.open_tcp_stream(
  File "C:\Users\PatCa\anaconda3\lib\site-packages\httpcore\_backends\anyio.py", line 154, in open_tcp_stream
    stream = await TLSStream.wrap(
  File "C:\Users\PatCa\anaconda3\lib\contextlib.py", line 131, in __exit__
    self.gen.throw(type, value, traceback)
  File "C:\Users\PatCa\anaconda3\lib\site-packages\httpcore\_exceptions.py", line 12, in map_exceptions
    raise to_exc(exc) from None
httpcore.ConnectError: [Errno 11001] getaddrinfo failed

The above exception was the direct cause of the following exception:

Traceback (most recent call last):
  File "C:\Users\PatCa\anaconda3\lib\site-packages\uvicorn\protocols\http\h11_impl.py", line 373, in run_asgi
    result = await app(self.scope, self.receive, self.send)
  File "C:\Users\PatCa\anaconda3\lib\site-packages\uvicorn\middleware\proxy_headers.py", line 75, in __call__
    return await self.app(scope, receive, send)
  File "C:\Users\PatCa\anaconda3\lib\site-packages\fastapi\applications.py", line 208, in __call__
    await super().__call__(scope, receive, send)
  File "C:\Users\PatCa\anaconda3\lib\site-packages\starlette\applications.py", line 112, in __call__
    await self.middleware_stack(scope, receive, send)
  File "C:\Users\PatCa\anaconda3\lib\site-packages\starlette\middleware\errors.py", line 181, in __call__
    raise exc
  File "C:\Users\PatCa\anaconda3\lib\site-packages\starlette\middleware\errors.py", line 159, in __call__
    await self.app(scope, receive, _send)
  File "C:\Users\PatCa\anaconda3\lib\site-packages\starlette\exceptions.py", line 82, in __call__
    raise exc
  File "C:\Users\PatCa\anaconda3\lib\site-packages\starlette\exceptions.py", line 71, in __call__
    await self.app(scope, receive, sender)
  File "C:\Users\PatCa\anaconda3\lib\site-packages\starlette\routing.py", line 656, in __call__
    await route.handle(scope, receive, send)
  File "C:\Users\PatCa\anaconda3\lib\site-packages\starlette\routing.py", line 259, in handle
    await self.app(scope, receive, send)
  File "C:\Users\PatCa\anaconda3\lib\site-packages\starlette\routing.py", line 61, in app
    response = await func(request)
  File "C:\Users\PatCa\anaconda3\lib\site-packages\fastapi\routing.py", line 226, in app
    raw_response = await run_endpoint_function(
  File "C:\Users\PatCa\anaconda3\lib\site-packages\fastapi\routing.py", line 159, in run_endpoint_function
    return await dependant.call(**values)
  File ".\app\main.py", line 130, in baby_dashboard
    weight_json = await get_weight()
  File ".\app\data_handler.py", line 19, in get_weight
    w_json = await client.get(adr + "weight")
  File "C:\Users\PatCa\anaconda3\lib\site-packages\httpx\_client.py", line 1704, in get
    return await self.request(
  File "C:\Users\PatCa\anaconda3\lib\site-packages\httpx\_client.py", line 1483, in request
    response = await self.send(
  File "C:\Users\PatCa\anaconda3\lib\site-packages\httpx\_client.py", line 1571, in send
    response = await self._send_handling_auth(
  File "C:\Users\PatCa\anaconda3\lib\site-packages\httpx\_client.py", line 1599, in _send_handling_auth
    response = await self._send_handling_redirects(
  File "C:\Users\PatCa\anaconda3\lib\site-packages\httpx\_client.py", line 1636, in _send_handling_redirects
    response = await self._send_single_request(request)
  File "C:\Users\PatCa\anaconda3\lib\site-packages\httpx\_client.py", line 1673, in _send_single_request
    response = await transport.handle_async_request(request)
  File "C:\Users\PatCa\anaconda3\lib\site-packages\httpx\_transports\default.py", line 271, in handle_async_request
    (
  File "C:\Users\PatCa\anaconda3\lib\contextlib.py", line 131, in __exit__
    self.gen.throw(type, value, traceback)
  File "C:\Users\PatCa\anaconda3\lib\site-packages\httpx\_transports\default.py", line 79, in map_httpcore_exceptions
    raise mapped_exc(message) from exc
httpx.ConnectError: [Errno 11001] getaddrinfo failed
2022-01-27 16:36:17,099 INFO     Shutting down
2022-01-27 16:36:26,276 INFO     Started server process [17060]
2022-01-27 16:36:26,276 INFO     Waiting for application startup.
2022-01-27 16:36:26,279 INFO     Application startup complete.
2022-01-27 16:36:57,356 INFO     Displaying dashboard
2022-01-27 16:39:23,878 INFO     Started server process [20792]
2022-01-27 16:39:23,878 INFO     Waiting for application startup.
2022-01-27 16:39:23,881 INFO     Application startup complete.
2022-01-27 16:39:28,564 INFO     Displaying dashboard
2022-01-27 16:39:37,238 INFO     Started server process [17948]
2022-01-27 16:39:37,239 INFO     Waiting for application startup.
2022-01-27 16:39:37,240 INFO     Application startup complete.
2022-01-27 16:39:40,628 INFO     Displaying dashboard
2022-01-27 16:39:50,268 INFO     Started server process [7628]
2022-01-27 16:39:50,269 INFO     Waiting for application startup.
2022-01-27 16:39:50,270 INFO     Application startup complete.
2022-01-27 16:41:25,638 INFO     Started server process [31848]
2022-01-27 16:41:25,638 INFO     Waiting for application startup.
2022-01-27 16:41:25,653 INFO     Application startup complete.
2022-01-27 16:41:30,282 INFO     Displaying dashboard
2022-01-27 16:41:46,498 INFO     Started server process [20688]
2022-01-27 16:41:46,499 INFO     Waiting for application startup.
2022-01-27 16:41:46,500 INFO     Application startup complete.
2022-01-27 16:45:43,280 INFO     Started server process [30556]
2022-01-27 16:45:43,281 INFO     Waiting for application startup.
2022-01-27 16:45:43,281 INFO     Application startup complete.
2022-01-27 16:45:47,542 INFO     Displaying dashboard
2022-01-27 16:49:13,889 INFO     Started server process [32604]
2022-01-27 16:49:13,889 INFO     Waiting for application startup.
2022-01-27 16:49:13,899 INFO     Application startup complete.
2022-01-27 16:49:32,413 INFO     Started server process [25724]
2022-01-27 16:49:32,414 INFO     Waiting for application startup.
2022-01-27 16:49:32,415 INFO     Application startup complete.
2022-01-27 16:49:34,099 ERROR    Exception in ASGI application
Traceback (most recent call last):
  File "C:\Users\PatCa\anaconda3\lib\site-packages\uvicorn\protocols\http\h11_impl.py", line 373, in run_asgi
    result = await app(self.scope, self.receive, self.send)
  File "C:\Users\PatCa\anaconda3\lib\site-packages\uvicorn\middleware\proxy_headers.py", line 75, in __call__
    return await self.app(scope, receive, send)
  File "C:\Users\PatCa\anaconda3\lib\site-packages\fastapi\applications.py", line 208, in __call__
    await super().__call__(scope, receive, send)
  File "C:\Users\PatCa\anaconda3\lib\site-packages\starlette\applications.py", line 112, in __call__
    await self.middleware_stack(scope, receive, send)
  File "C:\Users\PatCa\anaconda3\lib\site-packages\starlette\middleware\errors.py", line 181, in __call__
    raise exc
  File "C:\Users\PatCa\anaconda3\lib\site-packages\starlette\middleware\errors.py", line 159, in __call__
    await self.app(scope, receive, _send)
  File "C:\Users\PatCa\anaconda3\lib\site-packages\starlette\exceptions.py", line 82, in __call__
    raise exc
  File "C:\Users\PatCa\anaconda3\lib\site-packages\starlette\exceptions.py", line 71, in __call__
    await self.app(scope, receive, sender)
  File "C:\Users\PatCa\anaconda3\lib\site-packages\starlette\routing.py", line 656, in __call__
    await route.handle(scope, receive, send)
  File "C:\Users\PatCa\anaconda3\lib\site-packages\starlette\routing.py", line 259, in handle
    await self.app(scope, receive, send)
  File "C:\Users\PatCa\anaconda3\lib\site-packages\starlette\routing.py", line 61, in app
    response = await func(request)
  File "C:\Users\PatCa\anaconda3\lib\site-packages\fastapi\routing.py", line 226, in app
    raw_response = await run_endpoint_function(
  File "C:\Users\PatCa\anaconda3\lib\site-packages\fastapi\routing.py", line 159, in run_endpoint_function
    return await dependant.call(**values)
  File ".\app\main.py", line 148, in baby_dashboard
    plot_feeding(feeding_json.json(), weight_json.json())
  File ".\app\plot_util.py", line 209, in plot_feeding
    plt.margins([0.05,0.1])
  File "C:\Users\PatCa\anaconda3\lib\site-packages\matplotlib\pyplot.py", line 2684, in margins
    return gca().margins(*margins, x=x, y=y, tight=tight)
  File "C:\Users\PatCa\anaconda3\lib\site-packages\matplotlib\axes\_base.py", line 2734, in margins
    self.set_xmargin(x)
  File "C:\Users\PatCa\anaconda3\lib\site-packages\matplotlib\axes\_base.py", line 2634, in set_xmargin
    if m <= -0.5:
TypeError: '<=' not supported between instances of 'list' and 'float'
2022-01-27 16:49:55,200 INFO     Started server process [28052]
2022-01-27 16:49:55,200 INFO     Waiting for application startup.
2022-01-27 16:49:55,203 INFO     Application startup complete.
2022-01-27 16:49:58,478 ERROR    Exception in ASGI application
Traceback (most recent call last):
  File "C:\Users\PatCa\anaconda3\lib\site-packages\uvicorn\protocols\http\h11_impl.py", line 373, in run_asgi
    result = await app(self.scope, self.receive, self.send)
  File "C:\Users\PatCa\anaconda3\lib\site-packages\uvicorn\middleware\proxy_headers.py", line 75, in __call__
    return await self.app(scope, receive, send)
  File "C:\Users\PatCa\anaconda3\lib\site-packages\fastapi\applications.py", line 208, in __call__
    await super().__call__(scope, receive, send)
  File "C:\Users\PatCa\anaconda3\lib\site-packages\starlette\applications.py", line 112, in __call__
    await self.middleware_stack(scope, receive, send)
  File "C:\Users\PatCa\anaconda3\lib\site-packages\starlette\middleware\errors.py", line 181, in __call__
    raise exc
  File "C:\Users\PatCa\anaconda3\lib\site-packages\starlette\middleware\errors.py", line 159, in __call__
    await self.app(scope, receive, _send)
  File "C:\Users\PatCa\anaconda3\lib\site-packages\starlette\exceptions.py", line 82, in __call__
    raise exc
  File "C:\Users\PatCa\anaconda3\lib\site-packages\starlette\exceptions.py", line 71, in __call__
    await self.app(scope, receive, sender)
  File "C:\Users\PatCa\anaconda3\lib\site-packages\starlette\routing.py", line 656, in __call__
    await route.handle(scope, receive, send)
  File "C:\Users\PatCa\anaconda3\lib\site-packages\starlette\routing.py", line 259, in handle
    await self.app(scope, receive, send)
  File "C:\Users\PatCa\anaconda3\lib\site-packages\starlette\routing.py", line 61, in app
    response = await func(request)
  File "C:\Users\PatCa\anaconda3\lib\site-packages\fastapi\routing.py", line 226, in app
    raw_response = await run_endpoint_function(
  File "C:\Users\PatCa\anaconda3\lib\site-packages\fastapi\routing.py", line 159, in run_endpoint_function
    return await dependant.call(**values)
  File ".\app\main.py", line 148, in baby_dashboard
    plot_feeding(feeding_json.json(), weight_json.json())
  File ".\app\plot_util.py", line 209, in plot_feeding
    plt.margins([0,0.1])
  File "C:\Users\PatCa\anaconda3\lib\site-packages\matplotlib\pyplot.py", line 2684, in margins
    return gca().margins(*margins, x=x, y=y, tight=tight)
  File "C:\Users\PatCa\anaconda3\lib\site-packages\matplotlib\axes\_base.py", line 2734, in margins
    self.set_xmargin(x)
  File "C:\Users\PatCa\anaconda3\lib\site-packages\matplotlib\axes\_base.py", line 2634, in set_xmargin
    if m <= -0.5:
TypeError: '<=' not supported between instances of 'list' and 'float'
2022-01-27 16:50:09,751 INFO     Started server process [32364]
2022-01-27 16:50:09,751 INFO     Waiting for application startup.
2022-01-27 16:50:09,759 INFO     Application startup complete.
2022-01-27 16:50:14,023 INFO     Displaying dashboard
2022-01-27 16:50:26,411 INFO     Started server process [31768]
2022-01-27 16:50:26,412 INFO     Waiting for application startup.
2022-01-27 16:50:26,413 INFO     Application startup complete.
2022-01-27 16:50:29,926 INFO     Displaying dashboard
2022-01-27 16:50:37,197 INFO     Started server process [28452]
2022-01-27 16:50:37,197 INFO     Waiting for application startup.
2022-01-27 16:50:37,200 INFO     Application startup complete.
2022-01-27 16:50:40,415 INFO     Displaying dashboard
2022-01-28 16:28:55,844 INFO     Started server process [19336]
2022-01-28 16:28:55,844 INFO     Waiting for application startup.
2022-01-28 16:28:55,851 INFO     Application startup complete.
2022-01-28 16:29:00,183 INFO     Displaying dashboard
2022-01-28 16:29:07,863 INFO     Reset db
2022-01-28 16:29:17,706 INFO     Displaying dashboard
2022-01-28 16:31:48,492 INFO     Started server process [20644]
2022-01-28 16:31:48,492 INFO     Waiting for application startup.
2022-01-28 16:31:48,506 INFO     Application startup complete.
2022-01-28 16:31:53,584 INFO     Displaying dashboard
2022-01-28 16:32:26,820 INFO     Started server process [17132]
2022-01-28 16:32:26,820 INFO     Waiting for application startup.
2022-01-28 16:32:26,822 INFO     Application startup complete.
2022-01-28 16:39:37,220 INFO     Shutting down
2022-01-28 16:39:37,336 INFO     Waiting for application shutdown.
2022-01-28 16:39:37,337 INFO     Application shutdown complete.
2022-01-28 16:39:37,338 INFO     Finished server process [17132]
2022-01-28 16:47:21,215 INFO     Started server process [32392]
2022-01-28 16:47:21,216 INFO     Waiting for application startup.
2022-01-28 16:47:21,217 INFO     Application startup complete.
2022-01-28 16:47:44,132 ERROR    Exception in ASGI application
Traceback (most recent call last):
  File "C:\Users\PatCa\anaconda3\lib\site-packages\httpx\_transports\default.py", line 62, in map_httpcore_exceptions
    yield
  File "C:\Users\PatCa\anaconda3\lib\site-packages\httpx\_transports\default.py", line 276, in handle_async_request
    ) = await self._pool.handle_async_request(
  File "C:\Users\PatCa\anaconda3\lib\site-packages\httpcore\_async\connection_pool.py", line 234, in handle_async_request
    response = await connection.handle_async_request(
  File "C:\Users\PatCa\anaconda3\lib\site-packages\httpcore\_async\connection.py", line 136, in handle_async_request
    self.socket = await self._open_socket(timeout)
  File "C:\Users\PatCa\anaconda3\lib\site-packages\httpcore\_async\connection.py", line 163, in _open_socket
    return await self._backend.open_tcp_stream(
  File "C:\Users\PatCa\anaconda3\lib\site-packages\httpcore\_backends\auto.py", line 44, in open_tcp_stream
    return await self.backend.open_tcp_stream(
  File "C:\Users\PatCa\anaconda3\lib\site-packages\httpcore\_backends\anyio.py", line 154, in open_tcp_stream
    stream = await TLSStream.wrap(
  File "C:\Users\PatCa\anaconda3\lib\contextlib.py", line 131, in __exit__
    self.gen.throw(type, value, traceback)
  File "C:\Users\PatCa\anaconda3\lib\site-packages\httpcore\_exceptions.py", line 12, in map_exceptions
    raise to_exc(exc) from None
httpcore.ConnectError: All connection attempts failed

The above exception was the direct cause of the following exception:

Traceback (most recent call last):
  File "C:\Users\PatCa\anaconda3\lib\site-packages\uvicorn\protocols\http\h11_impl.py", line 373, in run_asgi
    result = await app(self.scope, self.receive, self.send)
  File "C:\Users\PatCa\anaconda3\lib\site-packages\uvicorn\middleware\proxy_headers.py", line 75, in __call__
    return await self.app(scope, receive, send)
  File "C:\Users\PatCa\anaconda3\lib\site-packages\fastapi\applications.py", line 208, in __call__
    await super().__call__(scope, receive, send)
  File "C:\Users\PatCa\anaconda3\lib\site-packages\starlette\applications.py", line 112, in __call__
    await self.middleware_stack(scope, receive, send)
  File "C:\Users\PatCa\anaconda3\lib\site-packages\starlette\middleware\errors.py", line 181, in __call__
    raise exc
  File "C:\Users\PatCa\anaconda3\lib\site-packages\starlette\middleware\errors.py", line 159, in __call__
    await self.app(scope, receive, _send)
  File "C:\Users\PatCa\anaconda3\lib\site-packages\starlette\exceptions.py", line 82, in __call__
    raise exc
  File "C:\Users\PatCa\anaconda3\lib\site-packages\starlette\exceptions.py", line 71, in __call__
    await self.app(scope, receive, sender)
  File "C:\Users\PatCa\anaconda3\lib\site-packages\starlette\routing.py", line 656, in __call__
    await route.handle(scope, receive, send)
  File "C:\Users\PatCa\anaconda3\lib\site-packages\starlette\routing.py", line 259, in handle
    await self.app(scope, receive, send)
  File "C:\Users\PatCa\anaconda3\lib\site-packages\starlette\routing.py", line 61, in app
    response = await func(request)
  File "C:\Users\PatCa\anaconda3\lib\site-packages\fastapi\routing.py", line 226, in app
    raw_response = await run_endpoint_function(
  File "C:\Users\PatCa\anaconda3\lib\site-packages\fastapi\routing.py", line 159, in run_endpoint_function
    return await dependant.call(**values)
  File ".\app\main.py", line 130, in baby_dashboard
    weight_json = await get_weight()
  File ".\app\data_handler.py", line 19, in get_weight
    w_json = await client.get(adr + "weight")
  File "C:\Users\PatCa\anaconda3\lib\site-packages\httpx\_client.py", line 1704, in get
    return await self.request(
  File "C:\Users\PatCa\anaconda3\lib\site-packages\httpx\_client.py", line 1483, in request
    response = await self.send(
  File "C:\Users\PatCa\anaconda3\lib\site-packages\httpx\_client.py", line 1571, in send
    response = await self._send_handling_auth(
  File "C:\Users\PatCa\anaconda3\lib\site-packages\httpx\_client.py", line 1599, in _send_handling_auth
    response = await self._send_handling_redirects(
  File "C:\Users\PatCa\anaconda3\lib\site-packages\httpx\_client.py", line 1636, in _send_handling_redirects
    response = await self._send_single_request(request)
  File "C:\Users\PatCa\anaconda3\lib\site-packages\httpx\_client.py", line 1673, in _send_single_request
    response = await transport.handle_async_request(request)
  File "C:\Users\PatCa\anaconda3\lib\site-packages\httpx\_transports\default.py", line 271, in handle_async_request
    (
  File "C:\Users\PatCa\anaconda3\lib\contextlib.py", line 131, in __exit__
    self.gen.throw(type, value, traceback)
  File "C:\Users\PatCa\anaconda3\lib\site-packages\httpx\_transports\default.py", line 79, in map_httpcore_exceptions
    raise mapped_exc(message) from exc
httpx.ConnectError: All connection attempts failed
2022-01-28 16:51:06,831 INFO     Displaying dashboard
2022-01-28 16:51:22,320 INFO     Updating head data
2022-01-28 16:51:26,712 INFO     Displaying dashboard
2022-01-28 16:51:33,637 INFO     Reset db
2022-01-28 16:51:38,111 INFO     Displaying dashboard
2022-01-28 16:52:05,250 INFO     Started server process [14304]
2022-01-28 16:52:05,250 INFO     Waiting for application startup.
2022-01-28 16:52:05,252 INFO     Application startup complete.
2022-01-29 07:56:54,785 INFO     Started server process [17964]
2022-01-29 07:56:54,786 INFO     Waiting for application startup.
2022-01-29 07:56:54,787 INFO     Application startup complete.
2022-01-29 07:56:57,191 INFO     Started server process [31324]
2022-01-29 07:56:57,191 INFO     Waiting for application startup.
2022-01-29 07:56:57,199 INFO     Application startup complete.
2022-01-29 07:57:23,687 INFO     Started server process [32552]
2022-01-29 07:57:23,687 INFO     Waiting for application startup.
2022-01-29 07:57:23,688 INFO     Application startup complete.
2022-01-29 07:58:10,818 INFO     Started server process [29536]
2022-01-29 07:58:10,819 INFO     Waiting for application startup.
2022-01-29 07:58:10,820 INFO     Application startup complete.
2022-01-29 07:58:20,733 INFO     Started server process [20632]
2022-01-29 07:58:20,741 INFO     Waiting for application startup.
2022-01-29 07:58:20,741 INFO     Application startup complete.
2022-01-29 08:00:13,392 INFO     Displaying dashboard
2022-01-29 08:41:56,224 INFO     Started server process [1768]
2022-01-29 08:41:56,225 INFO     Waiting for application startup.
2022-01-29 08:41:56,226 INFO     Application startup complete.
2022-01-29 08:42:26,703 INFO     Displaying dashboard
2022-01-29 10:03:56,965 INFO     Started server process [28604]
2022-01-29 10:03:56,966 INFO     Waiting for application startup.
2022-01-29 10:03:56,967 INFO     Application startup complete.
2022-01-29 10:04:05,546 INFO     Started server process [17040]
2022-01-29 10:04:05,546 INFO     Waiting for application startup.
2022-01-29 10:04:05,555 INFO     Application startup complete.
2022-01-29 10:04:59,867 INFO     Shutting down
